Workbook

Sheet 役員報酬・社保
B2: 💰 役員報酬・社会保険料 計算シート
B3: 月額報酬・賞与・経費枠を入力すると、等級表で社保自動計算＋実質手取りも算出されます。
B5: ■ 保険料率設定（令和8年度 滋賀県）
B6: 項目 | C6: 率 | D6: 備考
B7: 健康保険料率（滋賀県R8） | C7: 0.0988 | D7: 令和8年3月分から。協会けんぽ滋賀支部
B8: 介護保険料率 | C8: 0.0162 | D8: 全国一律。40歳以上64歳以下に適用
B9: 子育て支援金率 | C9: 0.0023 | D9: 全国一律。R8年4月分（5月納付）から
B10: 厚生年金保険料率 | C10: 0.183 | D10: 全国一律（法定）
B11: 子ども・子育て拠出金率 | C11: 0.0036 | D11: 事業主のみ負担（本人負担なし）
B13: データソース: 協会けんぽ R8保険料額表、厚労省（2026年2月時点）
B14: ※ 令和8年4月からは防衛特別法人税（法人税額の4%）も加算。本シートでは未反映
B15: ■ 役員報酬設定（月額・手入力）
B16: 項目 | C16: 坂本 | D16: 櫻井 | E16: 町田 | F16: 備考
B17: 月額報酬（定期同額給与） | C17: 62000 | D17: 62000 | E17: 62000 | F17: 毎月同額。年度途中変更不可
B18: 年齢（40歳以上なら介護保険） | C18: いいえ | D18: いいえ | E18: いいえ | F18: 40〜64歳は介護保険対象
B19: 介護保険 対象？（自動判定） | C19: =IF(C18="はい","〇","×") -> × | D19: =IF(D18="はい","〇","×") -> × | E19: =IF(E18="はい","〇","×") -> × | F19: 自動
B20: flat.で社保加入？ | C20: はい | D20: はい | E20: はい | F20: いいえ=国保+国民年金
B21: 年間賞与（事前確定届出給与） | C21: 0 | D21: 0 | F21: 年1回想定。届出額と1円違うと全額否認
B24: ■ 標準報酬月額 等級表（健康保険1-30等級 / 厚生年金1-27等級）
B25: 健保等級 | C25: 厚年等級 | D25: 標準報酬月額 | E25: 報酬月額 下限 | F25: 報酬月額 上限
B26: 1 | D26: 58000 | E26: 0 | F26: 63000
B27: 2 | D27: 68000 | E27: 63000 | F27: 73000
B28: 3 | D28: 78000 | E28: 73000 | F28: 83000
B29: 4 | C29: 1 | D29: 88000 | E29: 83000 | F29: 93000
B30: 5 | C30: 2 | D30: 98000 | E30: 93000 | F30: 101000
B31: 6 | C31: 3 | D31: 104000 | E31: 101000 | F31: 107000
B32: 7 | C32: 4 | D32: 110000 | E32: 107000 | F32: 114000
B33: 8 | C33: 5 | D33: 118000 | E33: 114000 | F33: 122000
B34: 9 | C34: 6 | D34: 126000 | E34: 122000 | F34: 130000
B35: 10 | C35: 7 | D35: 134000 | E35: 130000 | F35: 138000
B36: 11 | C36: 8 | D36: 142000 | E36: 138000 | F36: 146000
B37: 12 | C37: 9 | D37: 150000 | E37: 146000 | F37: 155000
B38: 13 | C38: 10 | D38: 160000 | E38: 155000 | F38: 165000
B39: 14 | C39: 11 | D39: 170000 | E39: 165000 | F39: 175000
B40: 15 | C40: 12 | D40: 180000 | E40: 175000 | F40: 185000
... B55: 30 | C55: 27 | D55: 500000 | E55: 485000 | F55: 515000
B58: ■ 社会保険料 計算（月次）
B59: 項目 | C59: 坂本 | D59: 櫻井 | E59: 町田 | F59: 合計 | G59: 備考
B60: 標準報酬月額 | C60: =IF(C20="いいえ",0,IFERROR(INDEX($D$26:$D$55,MATCH(C17,$E$26:$E$55,1)),88000)) -> 58000 | D60: =IF(D20="いいえ",0,IFERROR(INDEX($D$26:$D$55,MATCH(D17,$E$26:$E$55,1)),88000)) -> 58000 | E60: =IF(E20="いいえ",0,IFERROR(INDEX($D$26:$D$55,MATCH(E17,$E$26:$E$55,1)),88000)) -> 58000 | F60: =SUM(C60:E60) -> 174000 | G60: 月額報酬から自動判定（加入していない人は0）
B61: 健康保険料（月額、会社+本人） | C61: =C60*($C$7+IF(C19="〇",$C$8,0)) -> 5730.4 | D61: =D60*($C$7+IF(D19="〇",$C$8,0)) -> 5730.4 | E61: =E60*($C$7+IF(E19="〇",$C$8,0)) -> 5730.4 | F61: =SUM(C61:E61) -> 17191.2 | G61: 介護対象者は+1.62%
...

Sheet freee実績
A1: 日付 | B1: 年月 | C1: 勘定科目 | D1: 品目 | E1: 金額 | F1: 取引ID | H1: ※このタブはfreee取込専用。B列「年月」はYYYY-MM形式の文字列で入れること（例: 2026-08）。月次シートのSUMIFSがこの値で集計する。

Sheet 4月
B1: ☕ カフェ経営管理 ─ 4月 | U1: ■ 計画値（売上計画シートから自動取得）
B2: 月末口座（人件費なし） | C2: =I75 -> 0 | E2: 今月出ていくお金 | F2: =C16+SUM(C20:C23)+SUM(C25:C28)+M36+D54+M41 -> 0 | H2: 今月の利益 | I2: =I39 -> 0 | L2: 来月必要なお金 | M2: ='5月'!C20+'5月'!C21+'5月'!C22+'5月'!C23+'5月'!C25 -> 0 | U2: 実績の入力時に参考にしてください。差額・達成率も自動表示。
B3: ■ 資金（期首残高） | G3: ■ 売上（定期収入） | L3: ■ 人件費計算
B4: 科目 | C4: 金額 | D4: 詳細 | E4: メモ | G4: カテゴリ | H4: 金額 | I4: 詳細 | J4: メモ | L4: スタッフ名 | M4: 時給 | N4: 日数 | O4: 時間/日 | P4: 交通費/日 | Q4: 小計（給与） | R4: 小計（交通費） | U4: ■ 売上
B5: 自己資金（資本金） | G5: ドリンク（コーヒー） | H5: ='4月日次売上'!C34 -> 0 | Q5: =M5*N5*O5 -> 0 | R5: =P5*N5 -> 0 | U5: 項目 | V5: 計画 | W5: 実績 | X5: 差額 | Y5: 達成率
B6: 追加資金（借入等） | G6: ドリンク（紅茶・その他） | H6: ='4月日次売上'!D34 -> 0 | Q6: =M6*N6*O6 -> 0 | R6: =P6*N6 -> 0 | U6: 昼 来客数（季節調整後）/日 | V6: ='売上計画'!C38 -> 0 | W6: =IF(H26=0,"",H24/H26/2) | X6: =IF(W6="",0,W6-V6) -> 0 | Y6: =IF(OR(W6="",V6=0),0,W6/V6) -> 0
B7: 期首資金 合計 | C7: =SUM(C5:C6) -> 0 | G7: フード（軽食） | H7: ='4月日次売上'!E34 -> 0 | Q7: =M7*N7*O7 -> 0 | R7: =P7*N7 -> 0 | U7: 夜 来客数（季節調整後）/日 | V7: ='売上計画'!C39 -> 0 | W7: =IF(H26=0,"",H24/H26/2) | X7: =IF(W7="",0,W7-V7) -> 0 | Y7: =IF(OR(W7="",V7=0),0,W7/V7) -> 0
G8: フード（スイーツ） | H8: ='4月日次売上'!F34 -> 0 | Q8: =M8*N8*O8 -> 0 | R8: =P8*N8 -> 0 | U8: 売上合計（月間） | V8: ='売上計画'!C45 -> 0 | W8: =H20 -> 0 | X8: =W8-V8 -> 0 | Y8: =IF(V8=0,0,W8/V8) -> 0
B9: ■ 原価（売上原価） | G9: 物販（コーヒー豆・グッズ） | H9: ='4月日次売上'!G34 -> 0 | Q9: =M9*N9*O9 -> 0 | R9: =P9*N9 -> 0 | U9: 客単価 | V9: =IF((V6*'売上計画'!$C$7+V7*'売上計画'!$C$8)=0,0,V8/(V6*'売上計画'!$C$7+V7*'売上計画'!$C$8)) -> 0 | W9: =H25 -> 0 | X9: =W9-V9 -> 0 | Y9: =IF(V9=0,0,W9/V9) -> 0
B10: 科目 | C10: 金額 | D10: 詳細 | E10: メモ | G10: テイクアウト | H10: ='4月日次売上'!H34 -> 0 | Q10: =M10*N10*O10 -> 0 | R10: =P10*N10 -> 0
B11: コーヒー豆・茶葉 | C11: =SUMIFS('freee実績'!$E:$E,'freee実績'!$B:$B,"2026-04",'freee実績'!$C:$C,"仕入高",'freee実績'!$D:$D,"コーヒー豆・茶葉") -> 0 | G11: 売上 合計 | H11: =SUM(H5:H10) -> 0 | Q11: =M11*N11*O11 -> 0 | R11: =P11*N11 -> 0 | U11: ■ 原価・粗利
B12: 牛乳・シロップ等 | C12: =SUMIFS('freee実績'!$E:$E,'freee実績'!$B:$B,"2026-04",'freee実績'!$C:$C,"仕入高",'freee実績'!$D:$D,"牛乳・シロップ等") -> 0 | Q12: =M12*N12*O12 -> 0 | R12: =P12*N12 -> 0 | U12: 項目 | V12: 計画 | W12: 実績 | X12: 差額 | Y12: 原価率
B13: フード材料費 | C13: =SUMIFS('freee実績'!$E:$E,'freee実績'!$B:$B,"2026-04",'freee実績'!$C:$C,"仕入高",'freee実績'!$D:$D,"フード材料費") -> 0 | G13: ■ その他収入（不定期） | L13: アルバイト給与 合計 | Q13: =SUM(Q5:Q12) -> 0 | R13: =SUM(R5:R12) -> 0 | U13: 原価合計 | V13: ='売上計画'!C46 -> 0 | W13: =C16 -> 0 | X13: =W13-V13 -> 0 | Y13: =IF(W8=0,0,W13/W8) -> 0
B14: 包装資材・消耗品 | C14: =SUMIFS('freee実績'!$E:$E,'freee実績'!$B:$B,"2026-04",'freee実績'!$C:$C,"仕入高",'freee実績'!$D:$D,"包装資材・消耗品") -> 0 | G14: カテゴリ | H14: 金額 | I14: 詳細 | J14: メモ | U14: 粗利益 | V14: ='売上計画'!C47 -> 0 | W14: =H20-C16 -> 0 | X14: =W14-V14 -> 0 | Y14: =IF(W8=0,0,W14/W8) -> 0
B15: その他原価 | C15: =SUMIFS('freee実績'!$E:$E,'freee実績'!$B:$B,"2026-04",'freee実績'!$C:$C,"仕入高",'freee実績'!$D:$D,"その他原価") -> 0 | G15: イベント・貸切 | H15: ='4月日次売上'!I34 -> 0 | L15: ■ 固定人件費（役員報酬・社員給与等）
B16: 原価 合計 | C16: =SUM(C11:C15) -> 0 | G16: その他収入② | L16: 項目 | M16: 月額 | R16: 備考 | U16: ■ 経費
G17: その他収入 | L17: 役員報酬 | U17: 項目 | V17: 計画 | W17: 実績 | X17: 差額
B18: ■ 経費（販管費） | G18: その他収入 合計 | H18: =SUM(H15:H17) -> 0 | L18: 社員給与 | U18: 人件費（バイト+固定） | V18: ='売上計画'!C54 -> 0 | W18: =C24 -> 0 | X18: =W18-V18 -> 0
B19: 科目 | C19: 金額 | D19: 詳細 | E19: メモ | L19: 社会保険料（会社負担） | U19: 固定費（家賃+光熱+通信+保険） | V19: ='売上計画'!C57 -> 0 | W19: =C20+C21+C22+C23 -> 0 | X19: =W19-V19 -> 0
B20: 家賃 | C20: =SUMIFS('freee実績'!$E:$E,'freee実績'!$B:$B,"2026-04",'freee実績'!$C:$C,"地代家賃") -> 0 | D20: 固定費 | G20: 売上合計（定期＋不定期） | H20: =H11+H18 -> 0 | L20: その他人件費 | U20: 消耗品 | V20: ='売上計画'!C58 -> 0 | W20: =C25 -> 0 | X20: =W20-V20 -> 0
B21: 水道光熱費 | C21: =SUMIFS('freee実績'!$E:$E,'freee実績'!$B:$B,"2026-04",'freee実績'!$C:$C,"水道光熱費") -> 0 | D21: 固定費 | L21: 固定人件費 合計 | M21: =SUM(M17:M20) -> 0 | U21: 経費合計 | V21: ='売上計画'!C59 -> 0 | W21: =C30 -> 0 | X21: =W21-V21 -> 0
B22: 通信費 | C22: =SUMIFS('freee実績'!$E:$E,'freee実績'!$B:$B,"2026-04",'freee実績'!$C:$C,"通信費") -> 0 | D22: 固定費 | G22: ■ 売上KPI
B23: 保険料 | C23: =SUMIFS('freee実績'!$E:$E,'freee実績'!$B:$B,"2026-04",'freee実績'!$C:$C,"保険料") -> 0 | D23: 固定費 | G23: 指標 | H23: 数値 | J23: 算出方法 | L23: 人件費 総合計 | M23: =Q13+R13+M21 -> 0 | U23: ■ 営業利益
B24: 人件費（給与・社保） | C24: =M23 -> 0 | D24: 変動費 | G24: 来客数（人） | H24: ='4月日次売上'!J34 -> 0 | U24: 項目 | V24: 計画 | W24: 実績 | X24: 差額 | Y24: 達成率
B25: 消耗品費 | C25: =SUMIFS('freee実績'!$E:$E,'freee実績'!$B:$B,"2026-04",'freee実績'!$C:$C,"消耗品費") -> 0 | D25: 変動費 | G25: 客単価 | H25: =IF(H24=0,0,H20/H24) -> 0 | J25: 売上÷来客数 | L25: ↑ この金額を左側「人件費（給与・社保）」に転記 | U25: 営業利益 | V25: ='売上計画'!C61 | W25: =I39 -> 0 | X25: =W25-V25 -> 0 | Y25: =IF(V25=0,0,W25/V25) -> 0
B26: 広告宣伝費 | C26: =SUMIFS('freee実績'!$E:$E,'freee実績'!$B:$B,"2026-04",'freee実績'!$C:$C,"広告宣伝費") -> 0 | D26: 変動費 | G26: 営業日数 | H26: 0 | U26: 営業利益率 | V26: ='売上計画'!C62 -> 0 | W26: =IF(W8=0,0,W25/W8) -> 0 | X26: =W26-V26 -> 0
B27: 修繕費 | C27: =SUMIFS('freee実績'!$E:$E,'freee実績'!$B:$B,"2026-04",'freee実績'!$C:$C,"修繕費") -> 0 | D27: 変動費 | G27: 日商（1日平均売上） | H27: =IF(H26=0,0,H20/H26) -> 0 | J27: 売上÷営業日数 | L27: ■ 人件費KPI
B28: その他経費 | C28: =SUMIFS('freee実績'!$E:$E,'freee実績'!$B:$B,"2026-04",'freee実績'!$C:$C,"雑費") -> 0 | D28: 変動費 | G28: 原価率 | H28: =IF(H20=0,0,C16/H20) -> 0 | J28: 原価÷売上 | L28: 指標 | M28: 数値 | R28: 算出方法
B29: 減価償却費 | C29: ='固定資産台帳'!L26 -> 0 | D29: 帳簿上のみ | L29: 人件費率 | M29: =IF(H20=0,0,M23/H20) -> 0 | R29: 人件費÷売上
B30: 経費 合計 | C30: =SUM(C20:C29) -> 0 | L30: 人時売上高 | M30: =IF((SUM(N5:N12)*SUM(O5:O12))=0,0,H20/(SUM(N5:N12)*SUM(O5:O12))) -> 0 | R30: 売上÷総労働時間
B32: ■ 一括経費（設備投資等） | G32: ■ 月次損益計算 | L32: ■ オーナー人件費 未払い管理
B33: 科目 | C33: 予算 | D33: 実績 | E33: 差額（残） | F33: メモ | H33: 項目 | I33: 金額 | L33: 帳簿上は計上、実際の支払いは利益が出てから
H34: 売上高 | I34: =H20 -> 0 | L34: 今月の人件費 支払い？ | M34: 未払い | N34: ← 「支払い」か「未払い」を入力
E35: =C35-D35 -> 0 | H35: 原価合計 | I35: =C16 -> 0 | L35: 人件費（帳簿計上額） | M35: =M23 -> 0 | N35: P/Lに反映
E36: =C36-D36 -> 0 | H36: 粗利益 | I36: =I34-I35 -> 0 | L36: 実際の支払い額 | M36: =IF(M34="支払い",M35,0) -> 0 | N36: 口座から出るお金
E37: =C37-D37 -> 0 | H37: 粗利率 | I37: =IF(I34=0,0,I36/I34) -> 0 | L37: 今月の未払い額 | M37: =M35-M36 -> 0 | N37: 帳簿上は経費だが現金は出ない
E38: =C38-D38 -> 0 | H38: 経費合計 | I38: =C30 -> 0 | L38: 前月までの未払い累計 | M38: 0
E39: =C39-D39 -> 0 | H39: 営業利益 | I39: =I36-I38 -> 0 | L39: 未払い累計（今月末時点） | M39: =M38+M37 -> 0 | N39: 将来支払う必要のある額
E40: =C40-D40 -> 0
E41: =C41-D41 -> 0 | L41: 過去の未払い分 今月支払額 | N41: 未払い累計から取り崩す場合に入力
...

Sheet 5月
B1: ☕ カフェ経営管理 ─ 5月 | U1: ■ 計画値（売上計画シートから自動取得）
B2: 月末口座（人件費なし） | C2: =I75 -> 2886000 | E2: 今月出ていくお金 | F2: =C16+SUM(C20:C23)+SUM(C25:C28)+M36+D54+M41 -> 114000 | H2: 今月の利益 | I2: =I39 -> 0 | L2: 来月必要なお金 | M2: ='6月'!C20+'6月'!C21+'6月'!C22+'6月'!C23+'6月'!C25 -> 0 | U2: 実績の入力時に参考にしてください。差額・達成率も自動表示。
B3: ■ 資金（期首残高） | G3: ■ 売上（定期収入） | L3: ■ 人件費計算
B4: 科目 | C4: 金額 | D4: 詳細 | E4: メモ | G4: カテゴリ | H4: 金額 | I4: 詳細 | J4: メモ | L4: スタッフ名 | M4: 時給 | N4: 日数 | O4: 時間/日 | P4: 交通費/日 | Q4: 小計（給与） | R4: 小計（交通費） | U4: ■ 売上
B5: 前月繰越金 | C5: 3000000 | E5: 出資金合計300万円(創業メンバー4名による出資) | G5: ドリンク（コーヒー） | H5: ='5月日次売上'!C35 -> 0 | Q5: =M5*N5*O5 -> 0 | R5: =P5*N5 -> 0 | U5: 項目 | V5: 計画 | W5: 実績 | X5: 差額 | Y5: 達成率
B6: 追加資金（借入等） | G6: ドリンク（紅茶・その他） | H6: ='5月日次売上'!D35 -> 0 | Q6: =M6*N6*O6 -> 0 | R6: =P6*N6 -> 0 | U6: 昼 来客数（季節調整後）/日 | V6: ='売上計画'!D38 -> 0 | W6: =IF(H26=0,"",H24/H26/2) | X6: =IF(W6="",0,W6-V6) -> 0 | Y6: =IF(OR(W6="",V6=0),0,W6/V6) -> 0
B7: 期首資金 合計 | C7: =SUM(C5:C6) -> 3000000 | G7: フード（軽食） | H7: ='5月日次売上'!E35 -> 0 | Q7: =M7*N7*O7 -> 0 | R7: =P7*N7 -> 0 | U7: 夜 来客数（季節調整後）/日 | V7: ='売上計画'!D39 -> 0 | W7: =IF(H26=0,"",H24/H26/2) | X7: =IF(W7="",0,W7-V7) -> 0 | Y7: =IF(OR(W7="",V7=0),0,W7/V7) -> 0
G8: フード（スイーツ） | H8: ='5月日次売上'!F35 -> 0 | Q8: =M8*N8*O8 -> 0 | R8: =P8*N8 -> 0 | U8: 売上合計（月間） | V8: ='売上計画'!D45 -> 0 | W8: =H20 -> 0 | X8: =W8-V8 -> 0 | Y8: =IF(V8=0,0,W8/V8) -> 0
B9: ■ 原価（売上原価） | G9: 物販（コーヒー豆・グッズ） | H9: ='5月日次売上'!G35 -> 0 | Q9: =M9*N9*O9 -> 0 | R9: =P9*N9 -> 0 | U9: 客単価 | V9: =IF((V6*'売上計画'!$C$7+V7*'売上計画'!$C$8)=0,0,V8/(V6*'売上計画'!$C$7+V7*'売上計画'!$C$8)) -> 0 | W9: =H25 -> 0 | X9: =W9-V9 -> 0 | Y9: =IF(V9=0,0,W9/V9) -> 0
B10: 科目 | C10: 金額 | D10: 詳細 | E10: メモ | G10: テイクアウト | H10: ='5月日次売上'!H35 -> 0 | Q10: =M10*N10*O10 -> 0 | R10: =P10*N10 -> 0
B11: コーヒー豆・茶葉 | C11: =SUMIFS('freee実績'!$E:$E,'freee実績'!$B:$B,"2026-05",'freee実績'!$C:$C,"仕入高",'freee実績'!$D:$D,"コーヒー豆・茶葉") -> 0 | G11: 売上 合計 | H11: =SUM(H5:H10) -> 0 | Q11: =M11*N11*O11 -> 0 | R11: =P11*N11 -> 0 | U11: ■ 原価・粗利
B12: 牛乳・シロップ等 | C12: =SUMIFS('freee実績'!$E:$E,'freee実績'!$B:$B,"2026-05",'freee実績'!$C:$C,"仕入高",'freee実績'!$D:$D,"牛乳・シロップ等") -> 0 | Q12: =M12*N12*O12 -> 0 | R12: =P12*N12 -> 0 | U12: 項目 | V12: 計画 | W12: 実績 | X12: 差額 | Y12: 原価率
B13: フード材料費 | C13: =SUMIFS('freee実績'!$E:$E,'freee実績'!$B:$B,"2026-05",'freee実績'!$C:$C,"仕入高",'freee実績'!$D:$D,"フード材料費") -> 0 | G13: ■ その他収入（不定期） | L13: アルバイト給与 合計 | Q13: =SUM(Q5:Q12) -> 0 | R13: =SUM(R5:R12) -> 0 | U13: 原価合計 | V13: ='売上計画'!D46 -> 0 | W13: =C16 -> 0 | X13: =W13-V13 -> 0 | Y13: =IF(W8=0,0,W13/W8) -> 0
B14: 包装資材・消耗品 | C14: =SUMIFS('freee実績'!$E:$E,'freee実績'!$B:$B,"2026-05",'freee実績'!$C:$C,"仕入高",'freee実績'!$D:$D,"包装資材・消耗品") -> 0 | G14: カテゴリ | H14: 金額 | I14: 詳細 | J14: メモ | U14: 粗利益 | V14: ='売上計画'!D47 -> 0 | W14: =H20-C16 -> 0 | X14: =W14-V14 -> 0 | Y14: =IF(W8=0,0,W14/W8) -> 0
B15: その他原価 | C15: =SUMIFS('freee実績'!$E:$E,'freee実績'!$B:$B,"2026-05",'freee実績'!$C:$C,"仕入高",'freee実績'!$D:$D,"その他原価") -> 0 | G15: イベント・貸切 | H15: ='5月日次売上'!I35 -> 0 | L15: ■ 固定人件費（役員報酬・社員給与等）
B16: 原価 合計 | C16: =SUM(C11:C15) -> 0 | G16: その他収入② | L16: 項目 | M16: 月額 | R16: 備考 | U16: ■ 経費
G17: その他収入 | L17: 役員報酬 | U17: 項目 | V17: 計画 | W17: 実績 | X17: 差額
B18: ■ 経費（販管費） | G18: その他収入 合計 | H18: =SUM(H15:H17) -> 0 | L18: 社員給与 | U18: 人件費（バイト+固定） | V18: ='売上計画'!D54 -> 0 | W18: =C24 -> 0 | X18: =W18-V18 -> 0
B19: 科目 | C19: 金額 | D19: 詳細 | E19: メモ | L19: 社会保険料（会社負担） | U19: 固定費（家賃+光熱+通信+保険） | V19: ='売上計画'!D57 -> 0 | W19: =C20+C21+C22+C23 -> 0 | X19: =W19-V19 -> 0
B20: 家賃 | C20: =SUMIFS('freee実績'!$E:$E,'freee実績'!$B:$B,"2026-05",'freee実績'!$C:$C,"地代家賃") -> 0 | D20: 固定費 | G20: 売上合計（定期＋不定期） | H20: =H11+H18 -> 0 | L20: その他人件費 | U20: 消耗品 | V20: ='売上計画'!D58 -> 0 | W20: =C25 -> 0 | X20: =W20-V20 -> 0
B21: 水道光熱費 | C21: =SUMIFS('freee実績'!$E:$E,'freee実績'!$B:$B,"2026-05",'freee実績'!$C:$C,"水道光熱費") -> 0 | D21: 固定費 | L21: 固定人件費 合計 | M21: =SUM(M17:M20) -> 0 | U21: 経費合計 | V21: ='売上計画'!D59 -> 0 | W21: =C30 -> 0 | X21: =W21-V21 -> 0
B22: 通信費 | C22: =SUMIFS('freee実績'!$E:$E,'freee実績'!$B:$B,"2026-05",'freee実績'!$C:$C,"通信費") -> 0 | D22: 固定費 | G22: ■ 売上KPI
B23: 保険料 | C23: =SUMIFS('freee実績'!$E:$E,'freee実績'!$B:$B,"2026-05",'freee実績'!$C:$C,"保険料") -> 0 | D23: 固定費 | G23: 指標 | H23: 数値 | J23: 算出方法 | L23: 人件費 総合計 | M23: =Q13+R13+M21 -> 0 | U23: ■ 営業利益
B24: 人件費（給与・社保） | C24: =M23 -> 0 | D24: 変動費 | G24: 来客数（人） | H24: ='5月日次売上'!J35 -> 0 | U24: 項目 | V24: 計画 | W24: 実績 | X24: 差額 | Y24: 達成率
B25: 消耗品費 | C25: =SUMIFS('freee実績'!$E:$E,'freee実績'!$B:$B,"2026-05",'freee実績'!$C:$C,"消耗品費") -> 0 | D25: 変動費 | G25: 客単価 | H25: =IF(H24=0,0,H20/H24) -> 0 | J25: 売上÷来客数 | L25: ↑ この金額を左側「人件費（給与・社保）」に転記 | U25: 営業利益 | V25: ='売上計画'!D61 | W25: =I39 -> 0 | X25: =W25-V25 -> 0 | Y25: =IF(V25=0,0,W25/V25) -> 0
B26: 広告宣伝費 | C26: =SUMIFS('freee実績'!$E:$E,'freee実績'!$B:$B,"2026-05",'freee実績'!$C:$C,"広告宣伝費") -> 0 | D26: 変動費 | G26: 営業日数 | H26: 0 | U26: 営業利益率 | V26: ='売上計画'!D62 -> 0 | W26: =IF(W8=0,0,W25/W8) -> 0 | X26: =W26-V26 -> 0
B27: 修繕費 | C27: =SUMIFS('freee実績'!$E:$E,'freee実績'!$B:$B,"2026-05",'freee実績'!$C:$C,"修繕費") -> 0 | D27: 変動費 | G27: 日商（1日平均売上） | H27: =IF(H26=0,0,H20/H26) -> 0 | J27: 売上÷営業日数 | L27: ■ 人件費KPI
B28: その他経費 | C28: =SUMIFS('freee実績'!$E:$E,'freee実績'!$B:$B,"2026-05",'freee実績'!$C:$C,"雑費") -> 0 | D28: 変動費 | G28: 原価率 | H28: =IF(H20=0,0,C16/H20) -> 0 | J28: 原価÷売上 | L28: 指標 | M28: 数値 | R28: 算出方法
B29: 減価償却費 | C29: ='固定資産台帳'!M26 -> 0 | D29: 帳簿上のみ | L29: 人件費率 | M29: =IF(H20=0,0,M23/H20) -> 0 | R29: 人件費÷売上
B30: 経費 合計 | C30: =SUM(C20:C29) -> 0 | L30: 人時売上高 | M30: =IF((SUM(N5:N12)*SUM(O5:O12))=0,0,H20/(SUM(N5:N12)*SUM(O5:O12))) -> 0 | R30: 売上÷総労働時間
B32: ■ 一括経費（設備投資等） | G32: ■ 月次損益計算 | L32: ■ オーナー人件費 未払い管理
B33: 科目 | C33: 予算 | D33: 実績 | E33: 差額（残） | F33: メモ | H33: 項目 | I33: 金額 | L33: 帳簿上は計上、実際の支払いは利益が出てから
B34: 設備購入 | E34: =C34-D34 -> 0 | H34: 売上高 | I34: =H20 -> 0 | L34: 今月の人件費 支払い？ | M34: 未払い | N34: ← 「支払い」か「未払い」を入力
B35: 内装工事 | E35: =C35-D35 -> 0 | H35: 原価合計 | I35: =C16 -> 0 | L35: 人件費（帳簿計上額） | M35: =M23 -> 0 | N35: P/Lに反映
B36: その他一括経費 | E36: =C36-D36 -> 0 | H36: 粗利益 | I36: =I34-I35 -> 0 | L36: 実際の支払い額 | M36: =IF(M34="支払い",M35,0) -> 0 | N36: 口座から出るお金
H37: 粗利率 | I37: =IF(I34=0,0,I36/I34) -> 0 | L37: 今月の未払い額 | M37: =M35-M36 -> 0 | N37: 帳簿上は経費だが現金は出ない
H38: 経費合計 | I38: =C30 -> 0 | L38: 前月までの未払い累計 | M38: ='4月'!M39 -> 0
H39: 営業利益 | I39: =I36-I38 -> 0 | L39: 未払い累計（今月末時点） | M39: =M38+M37 -> 0 | N39: 将来支払う必要のある額
B40: 許認可・法人設立費 | C40: 114000 | D40: 114000 | E40: =C40-D40 -> 0 | F40: 設立6万+印鑑1万+飲食1.8万+菓子1.6万+衛生1万
E41: =C41-D41 -> 0 | L41: 過去の未払い分 今月支払額 | N41: 未払い累計から取り崩す場合に入力
...

Sheet 6月
B1: ☕ カフェ経営管理 ─ 6月 | U1: ■ 計画値（売上計画シートから自動取得）
B2: 月末口座（人件費なし） | C2: =I75 -> 939612 | E2: 今月出ていくお金 | F2: =C16+SUM(C20:C23)+SUM(C25:C28)+M36+D54+M41 -> 1946388 | H2: 今月の利益 | I2: =I39 -> -14433.833 | L2: 来月必要なお金 | M2: ='7月'!C20+'7月'!C21+'7月'!C22+'7月'!C23+'7月'!C25 -> 0 | U2: 実績の入力時に参考にしてください。差額・達成率も自動表示。
B3: ■ 資金（期首残高） | G3: ■ 売上（定期収入） | L3: ■ 人件費計算
B4: 科目 | C4: 金額 | D4: 詳細 | E4: メモ | G4: カテゴリ | H4: 金額 | I4: 詳細 | J4: メモ | L4: スタッフ名 | M4: 時給 | N4: 日数 | O4: 時間/日 | P4: 交通費/日 | Q4: 小計（給与） | R4: 小計（交通費） | U4: ■ 売上
B5: 前月繰越金 | C5: ='5月'!I75 -> 2886000 | G5: ドリンク（コーヒー） | H5: ='6月日次売上'!C34 -> 0 | Q5: =M5*N5*O5 -> 0 | R5: =P5*N5 -> 0 | U5: 項目 | V5: 計画 | W5: 実績 | X5: 差額 | Y5: 達成率
B6: 追加資金（借入等） | G6: ドリンク（紅茶・その他） | H6: ='6月日次売上'!D34 -> 0 | Q6: =M6*N6*O6 -> 0 | R6: =P6*N6 -> 0 | U6: 昼 来客数（季節調整後）/日 | V6: ='売上計画'!E38 -> 0 | W6: =IF(H26=0,"",H24/H26/2) | X6: =IF(W6="",0,W6-V6) -> 0 | Y6: =IF(OR(W6="",V6=0),0,W6/V6) -> 0
B7: 期首資金 合計 | C7: =SUM(C5:C6) -> 2886000 | G7: フード（軽食） | H7: ='6月日次売上'!E34 -> 0 | Q7: =M7*N7*O7 -> 0 | R7: =P7*N7 -> 0 | U7: 夜 来客数（季節調整後）/日 | V7: ='売上計画'!E39 -> 0 | W7: =IF(H26=0,"",H24/H26/2) | X7: =IF(W7="",0,W7-V7) -> 0 | Y7: =IF(OR(W7="",V7=0),0,W7/V7) -> 0
G8: フード（スイーツ） | H8: ='6月日次売上'!F34 -> 0 | Q8: =M8*N8*O8 -> 0 | R8: =P8*N8 -> 0 | U8: 売上合計（月間） | V8: ='売上計画'!E45 -> 0 | W8: =H20 -> 0 | X8: =W8-V8 -> 0 | Y8: =IF(V8=0,0,W8/V8) -> 0
B9: ■ 原価（売上原価） | G9: 物販（コーヒー豆・グッズ） | H9: ='6月日次売上'!G34 -> 0 | Q9: =M9*N9*O9 -> 0 | R9: =P9*N9 -> 0 | U9: 客単価 | V9: =IF((V6*'売上計画'!$C$7+V7*'売上計画'!$C$8)=0,0,V8/(V6*'売上計画'!$C$7+V7*'売上計画'!$C$8)) -> 0 | W9: =H25 -> 0 | X9: =W9-V9 -> 0 | Y9: =IF(V9=0,0,W9/V9) -> 0
B10: 科目 | C10: 金額 | D10: 詳細 | E10: メモ | G10: テイクアウト | H10: ='6月日次売上'!H34 -> 0 | Q10: =M10*N10*O10 -> 0 | R10: =P10*N10 -> 0
B11: コーヒー豆・茶葉 | C11: =SUMIFS('freee実績'!$E:$E,'freee実績'!$B:$B,"2026-06",'freee実績'!$C:$C,"仕入高",'freee実績'!$D:$D,"コーヒー豆・茶葉") -> 0 | G11: 売上 合計 | H11: =SUM(H5:H10) -> 0 | Q11: =M11*N11*O11 -> 0 | R11: =P11*N11 -> 0 | U11: ■ 原価・粗利
B12: 牛乳・シロップ等 | C12: =SUMIFS('freee実績'!$E:$E,'freee実績'!$B:$B,"2026-06",'freee実績'!$C:$C,"仕入高",'freee実績'!$D:$D,"牛乳・シロップ等") -> 0 | Q12: =M12*N12*O12 -> 0 | R12: =P12*N12 -> 0 | U12: 項目 | V12: 計画 | W12: 実績 | X12: 差額 | Y12: 原価率
B13: フード材料費 | C13: =SUMIFS('freee実績'!$E:$E,'freee実績'!$B:$B,"2026-06",'freee実績'!$C:$C,"仕入高",'freee実績'!$D:$D,"フード材料費") -> 0 | G13: ■ その他収入（不定期） | L13: アルバイト給与 合計 | Q13: =SUM(Q5:Q12) -> 0 | R13: =SUM(R5:R12) -> 0 | U13: 原価合計 | V13: ='売上計画'!E46 -> 0 | W13: =C16 -> 0 | X13: =W13-V13 -> 0 | Y13: =IF(W8=0,0,W13/W8) -> 0
B14: 包装資材・消耗品 | C14: =SUMIFS('freee実績'!$E:$E,'freee実績'!$B:$B,"2026-06",'freee実績'!$C:$C,"仕入高",'freee実績'!$D:$D,"包装資材・消耗品") -> 0 | G14: カテゴリ | H14: 金額 | I14: 詳細 | J14: メモ | U14: 粗利益 | V14: ='売上計画'!E47 -> 0 | W14: =H20-C16 -> 0 | X14: =W14-V14 -> 0 | Y14: =IF(W8=0,0,W14/W8) -> 0
B15: その他原価 | C15: =SUMIFS('freee実績'!$E:$E,'freee実績'!$B:$B,"2026-06",'freee実績'!$C:$C,"仕入高",'freee実績'!$D:$D,"その他原価") -> 0 | G15: イベント・貸切 | H15: ='6月日次売上'!I34 -> 0 | L15: ■ 固定人件費（役員報酬・社員給与等）
B16: 原価 合計 | C16: =SUM(C11:C15) -> 0 | G16: その他収入② | L16: 項目 | M16: 月額 | R16: 備考 | U16: ■ 経費
G17: その他収入 | L17: 役員報酬 | U17: 項目 | V17: 計画 | W17: 実績 | X17: 差額
B18: ■ 経費（販管費） | G18: その他収入 合計 | H18: =SUM(H15:H17) -> 0 | L18: 社員給与 | U18: 人件費（バイト+固定） | V18: ='売上計画'!E54 -> 0 | W18: =C24 -> 0 | X18: =W18-V18 -> 0
B19: 科目 | C19: 金額 | D19: 詳細 | E19: メモ | L19: 社会保険料（会社負担） | U19: 固定費（家賃+光熱+通信+保険） | V19: ='売上計画'!E57 -> 0 | W19: =C20+C21+C22+C23 -> 0 | X19: =W19-V19 -> 0
B20: 家賃 | C20: =SUMIFS('freee実績'!$E:$E,'freee実績'!$B:$B,"2026-06",'freee実績'!$C:$C,"地代家賃") -> 0 | D20: 固定費 | G20: 売上合計（定期＋不定期） | H20: =H11+H18 -> 0 | L20: その他人件費 | U20: 消耗品 | V20: ='売上計画'!E58 -> 0 | W20: =C25 -> 0 | X20: =W20-V20 -> 0
B21: 水道光熱費 | C21: =SUMIFS('freee実績'!$E:$E,'freee実績'!$B:$B,"2026-06",'freee実績'!$C:$C,"水道光熱費") -> 0 | D21: 固定費 | L21: 固定人件費 合計 | M21: =SUM(M17:M20) -> 0 | U21: 経費合計 | V21: ='売上計画'!E59 -> 0 | W21: =C30 -> 14433.833 | X21: =W21-V21 -> 14433.833
B22: 通信費 | C22: =SUMIFS('freee実績'!$E:$E,'freee実績'!$B:$B,"2026-06",'freee実績'!$C:$C,"通信費") -> 0 | D22: 固定費 | G22: ■ 売上KPI
B23: 保険料 | C23: =SUMIFS('freee実績'!$E:$E,'freee実績'!$B:$B,"2026-06",'freee実績'!$C:$C,"保険料") -> 0 | D23: 固定費 | G23: 指標 | H23: 数値 | J23: 算出方法 | L23: 人件費 総合計 | M23: =Q13+R13+M21 -> 0 | U23: ■ 営業利益
B24: 人件費（給与・社保） | C24: =M23 -> 0 | D24: 変動費 | G24: 来客数（人） | H24: ='6月日次売上'!J34 -> 0 | U24: 項目 | V24: 計画 | W24: 実績 | X24: 差額 | Y24: 達成率
B25: 消耗品費 | C25: =SUMIFS('freee実績'!$E:$E,'freee実績'!$B:$B,"2026-06",'freee実績'!$C:$C,"消耗品費") -> 0 | D25: 変動費 | G25: 客単価 | H25: =IF(H24=0,0,H20/H24) -> 0 | J25: 売上÷来客数 | L25: ↑ この金額を左側「人件費（給与・社保）」に転記 | U25: 営業利益 | V25: ='売上計画'!E61 | W25: =I39 -> -14433.833 | X25: =W25-V25 -> -14433.833 | Y25: =IF(V25=0,0,W25/V25) -> 0
B26: 広告宣伝費 | C26: =SUMIFS('freee実績'!$E:$E,'freee実績'!$B:$B,"2026-06",'freee実績'!$C:$C,"広告宣伝費") -> 0 | D26: 変動費 | G26: 営業日数 | H26: 0 | U26: 営業利益率 | V26: ='売上計画'!E62 -> 0 | W26: =IF(W8=0,0,W25/W8) -> 0 | X26: =W26-V26 -> 0
B27: 修繕費 | C27: =SUMIFS('freee実績'!$E:$E,'freee実績'!$B:$B,"2026-06",'freee実績'!$C:$C,"修繕費") -> 0 | D27: 変動費 | G27: 日商（1日平均売上） | H27: =IF(H26=0,0,H20/H26) -> 0 | J27: 売上÷営業日数 | L27: ■ 人件費KPI
B28: その他経費 | C28: =SUMIFS('freee実績'!$E:$E,'freee実績'!$B:$B,"2026-06",'freee実績'!$C:$C,"雑費") -> 0 | D28: 変動費 | G28: 原価率 | H28: =IF(H20=0,0,C16/H20) -> 0 | J28: 原価÷売上 | L28: 指標 | M28: 数値 | R28: 算出方法
B29: 減価償却費 | C29: ='固定資産台帳'!N26 -> 14433.833 | D29: 帳簿上のみ | L29: 人件費率 | M29: =IF(H20=0,0,M23/H20) -> 0 | R29: 人件費÷売上
B30: 経費 合計 | C30: =SUM(C20:C29) -> 14433.833 | L30: 人時売上高 | M30: =IF((SUM(N5:N12)*SUM(O5:O12))=0,0,H20/(SUM(N5:N12)*SUM(O5:O12))) -> 0 | R30: 売上÷総労働時間
B32: ■ 一括経費（設備投資等） | G32: ■ 月次損益計算 | L32: ■ オーナー人件費 未払い管理
B33: 科目 | C33: 予算 | D33: 実績 | E33: 差額（残） | F33: メモ | H33: 項目 | I33: 金額 | L33: 帳簿上は計上、実際の支払いは利益が出てから
B34: 敷金（5ヶ月分） | D34: 500000 | E34: =C34-D34 -> -500000 | F34: 北棟 | H34: 売上高 | I34: =H20 -> 0 | L34: 今月の人件費 支払い？ | M34: 未払い | N34: ← 「支払い」か「未払い」を入力
B35: 礼金（2ヶ月分） | D35: 200000 | E35: =C35-D35 -> -200000 | F35: 北棟 | H35: 原価合計 | I35: =C16 -> 0 | L35: 人件費（帳簿計上額） | M35: =M23 -> 0 | N35: P/Lに反映
B36: 仲介手数料 | D36: 100000 | E36: =C36-D36 -> -100000 | F36: 1ヶ月分 | H36: 粗利益 | I36: =I34-I35 -> 0 | L36: 実際の支払い額 | M36: =IF(M34="支払い",M35,0) -> 0 | N36: 口座から出るお金
B37: エスプレッソマシン① | C37: 250000 | D37: 250000 | E37: =C37-D37 -> 0 | F37: La Marzocco Linea Classic S-2（中古） | H37: 粗利率 | I37: =IF(I34=0,0,I36/I34) -> 0 | L37: 今月の未払い額 | M37: =M35-M36 -> 0 | N37: 帳簿上は経費だが現金は出ない
B38: 保険（火災・施設賠償・PL） | D38: 45000 | E38: =C38-D38 -> -45000 | F38: 3種 各15,000円/年 | H38: 経費合計 | I38: =C30 -> 14433.833 | L38: 前月までの未払い累計 | M38: ='5月'!M39 -> 0
B39: 製氷機 | D39: 82500 | E39: =C39-D39 -> -82500 | F39: ダイワ DRI-25LME1（中古） | H39: 営業利益 | I39: =I36-I38 -> -14433.833 | L39: 未払い累計（今月末時点） | M39: =M38+M37 -> 0 | N39: 将来支払う必要のある額
B41: コーヒーグラインダー | C41: 68888 | D41: 68888 | E41: =C41-D41 -> 0 | F41: Mazzer Super Jolly（中古） | L41: 過去の未払い分 今月支払額 | N41: 未払い累計から取り崩す場合に入力
B42: 内装工事着工 | D42: 700000
...

Sheet 7月
B1: ☕ カフェ経営管理 ─ 7月 | U1: ■ 計画値（売上計画シートから自動取得）
B2: 月末口座（人件費なし） | C2: =I75 -> 3983694 | E2: 今月出ていくお金 | F2: =C16+SUM(C20:C23)+SUM(C25:C28)+M36+D54+M41 -> 455918 | H2: 今月の利益 | I2: =I39 -> -14433.833 | L2: 来月必要なお金 | M2: ='8月'!C20+'8月'!C21+'8月'!C22+'8月'!C23+'8月'!C25 -> 0 | U2: 実績の入力時に参考にしてください。差額・達成率も自動表示。
B3: ■ 資金（期首残高） | G3: ■ 売上（定期収入） | L3: ■ 人件費計算
B4: 科目 | C4: 金額 | D4: 詳細 | E4: メモ | G4: カテゴリ | H4: 金額 | I4: 詳細 | J4: メモ | L4: スタッフ名 | M4: 時給 | N4: 日数 | O4: 時間/日 | P4: 交通費/日 | Q4: 小計（給与） | R4: 小計（交通費） | U4: ■ 売上
B5: 前月繰越金 | C5: ='6月'!I75 -> 939612 | G5: ドリンク（コーヒー） | H5: ='7月日次売上'!C35 -> 0 | Q5: =M5*N5*O5 -> 0 | R5: =P5*N5 -> 0 | U5: 項目 | V5: 計画 | W5: 実績 | X5: 差額 | Y5: 達成率
B6: 追加資金（借入等） | C6: 3500000 | E6: 日本政策金融公庫（300万） | G6: ドリンク（紅茶・その他） | H6: ='7月日次売上'!D35 -> 0 | Q6: =M6*N6*O6 -> 0 | R6: =P6*N6 -> 0 | U6: 昼 来客数（季節調整後）/日 | V6: ='売上計画'!F38 -> 0 | W6: =IF(H26=0,"",H24/H26/2) | X6: =IF(W6="",0,W6-V6) -> 0 | Y6: =IF(OR(W6="",V6=0),0,W6/V6) -> 0
B7: 期首資金 合計 | C7: =SUM(C5:C6) -> 4439612 | G7: フード（軽食） | H7: ='7月日次売上'!E35 -> 0 | Q7: =M7*N7*O7 -> 0 | R7: =P7*N7 -> 0 | U7: 夜 来客数（季節調整後）/日 | V7: ='売上計画'!F39 -> 0 | W7: =IF(H26=0,"",H24/H26/2) | X7: =IF(W7="",0,W7-V7) -> 0 | Y7: =IF(OR(W7="",V7=0),0,W7/V7) -> 0
G8: フード（スイーツ） | H8: ='7月日次売上'!F35 -> 0 | Q8: =M8*N8*O8 -> 0 | R8: =P8*N8 -> 0 | U8: 売上合計（月間） | V8: ='売上計画'!F45 -> 0 | W8: =H20 -> 0 | X8: =W8-V8 -> 0 | Y8: =IF(V8=0,0,W8/V8) -> 0
B9: ■ 原価（売上原価） | G9: 物販（コーヒー豆・グッズ） | H9: ='7月日次売上'!G35 -> 0 | Q9: =M9*N9*O9 -> 0 | R9: =P9*N9 -> 0 | U9: 客単価 | V9: =IF((V6*'売上計画'!$C$7+V7*'売上計画'!$C$8)=0,0,V8/(V6*'売上計画'!$C$7+V7*'売上計画'!$C$8)) -> 0 | W9: =H25 -> 0 | X9: =W9-V9 -> 0 | Y9: =IF(V9=0,0,W9/V9) -> 0
B10: 科目 | C10: 金額 | D10: 詳細 | E10: メモ | G10: テイクアウト | H10: ='7月日次売上'!H35 -> 0 | Q10: =M10*N10*O10 -> 0 | R10: =P10*N10 -> 0
B11: コーヒー豆・茶葉 | C11: =SUMIFS('freee実績'!$E:$E,'freee実績'!$B:$B,"2026-07",'freee実績'!$C:$C,"仕入高",'freee実績'!$D:$D,"コーヒー豆・茶葉") -> 0 | G11: 売上 合計 | H11: =SUM(H5:H10) -> 0 | Q11: =M11*N11*O11 -> 0 | R11: =P11*N11 -> 0 | U11: ■ 原価・粗利
B12: 牛乳・シロップ等 | C12: =SUMIFS('freee実績'!$E:$E,'freee実績'!$B:$B,"2026-07",'freee実績'!$C:$C,"仕入高",'freee実績'!$D:$D,"牛乳・シロップ等") -> 0 | Q12: =M12*N12*O12 -> 0 | R12: =P12*N12 -> 0 | U12: 項目 | V12: 計画 | W12: 実績 | X12: 差額 | Y12: 原価率
B13: フード材料費 | C13: =SUMIFS('freee実績'!$E:$E,'freee実績'!$B:$B,"2026-07",'freee実績'!$C:$C,"仕入高",'freee実績'!$D:$D,"フード材料費") -> 0 | G13: ■ その他収入（不定期） | L13: アルバイト給与 合計 | Q13: =SUM(Q5:Q12) -> 0 | R13: =SUM(R5:R12) -> 0 | U13: 原価合計 | V13: ='売上計画'!F46 -> 0 | W13: =C16 -> 0 | X13: =W13-V13 -> 0 | Y13: =IF(W8=0,0,W13/W8) -> 0
B14: 包装資材・消耗品 | C14: =SUMIFS('freee実績'!$E:$E,'freee実績'!$B:$B,"2026-07",'freee実績'!$C:$C,"仕入高",'freee実績'!$D:$D,"包装資材・消耗品") -> 0 | G14: カテゴリ | H14: 金額 | I14: 詳細 | J14: メモ | U14: 粗利益 | V14: ='売上計画'!F47 -> 0 | W14: =H20-C16 -> 0 | X14: =W14-V14 -> 0 | Y14: =IF(W8=0,0,W14/W8) -> 0
B15: その他原価 | C15: =SUMIFS('freee実績'!$E:$E,'freee実績'!$B:$B,"2026-07",'freee実績'!$C:$C,"仕入高",'freee実績'!$D:$D,"その他原価") -> 0 | G15: イベント・貸切 | H15: ='7月日次売上'!I35 -> 0 | L15: ■ 固定人件費（役員報酬・社員給与等）
B16: 原価 合計 | C16: =SUM(C11:C15) -> 0 | G16: その他収入② | L16: 項目 | M16: 月額 | R16: 備考 | U16: ■ 経費
G17: その他収入 | L17: 役員報酬 | U17: 項目 | V17: 計画 | W17: 実績 | X17: 差額
B18: ■ 経費（販管費） | G18: その他収入 合計 | H18: =SUM(H15:H17) -> 0 | L18: 社員給与 | U18: 人件費（バイト+固定） | V18: ='売上計画'!F54 -> 0 | W18: =C24 | X18: =W18-V18 -> 0
B19: 科目 | C19: 金額 | D19: 詳細 | E19: メモ | L19: 社会保険料（会社負担） | U19: 固定費（家賃+光熱+通信+保険） | V19: ='売上計画'!F57 -> 0 | W19: =C20+C21+C22+C23 -> 0 | X19: =W19-V19 -> 0
B20: 家賃 | C20: =SUMIFS('freee実績'!$E:$E,'freee実績'!$B:$B,"2026-07",'freee実績'!$C:$C,"地代家賃") -> 0 | D20: 固定費 | G20: 売上合計（定期＋不定期） | H20: =H11+H18 -> 0 | L20: その他人件費 | U20: 消耗品 | V20: ='売上計画'!F58 -> 0 | W20: =C25 -> 0 | X20: =W20-V20 -> 0
B21: 水道光熱費 | C21: =SUMIFS('freee実績'!$E:$E,'freee実績'!$B:$B,"2026-07",'freee実績'!$C:$C,"水道光熱費") -> 0 | D21: 固定費 | L21: 固定人件費 合計 | M21: =SUM(M17:M20) -> 0 | U21: 経費合計 | V21: ='売上計画'!F59 -> 0 | W21: =C30 -> 14433.833 | X21: =W21-V21 -> 14433.833
B22: 通信費 | C22: =SUMIFS('freee実績'!$E:$E,'freee実績'!$B:$B,"2026-07",'freee実績'!$C:$C,"通信費") -> 0 | D22: 固定費 | G22: ■ 売上KPI
B23: 保険料 | C23: =SUMIFS('freee実績'!$E:$E,'freee実績'!$B:$B,"2026-07",'freee実績'!$C:$C,"保険料") -> 0 | D23: 固定費 | G23: 指標 | H23: 数値 | J23: 算出方法 | L23: 人件費 総合計 | M23: =Q13+R13+M21 -> 0 | U23: ■ 営業利益
B24: 人件費（給与・社保） | D24: 変動費 | G24: 来客数（人） | H24: ='7月日次売上'!J35 -> 0 | U24: 項目 | V24: 計画 | W24: 実績 | X24: 差額 | Y24: 達成率
B25: 消耗品費 | C25: =SUMIFS('freee実績'!$E:$E,'freee実績'!$B:$B,"2026-07",'freee実績'!$C:$C,"消耗品費") -> 0 | D25: 変動費 | G25: 客単価 | H25: =IF(H24=0,0,H20/H24) -> 0 | J25: 売上÷来客数 | L25: ↑ この金額を左側「人件費（給与・社保）」に転記 | U25: 営業利益 | V25: ='売上計画'!F61 | W25: =I39 -> -14433.833 | X25: =W25-V25 -> -14433.833 | Y25: =IF(V25=0,0,W25/V25) -> 0
B26: 広告宣伝費 | C26: =SUMIFS('freee実績'!$E:$E,'freee実績'!$B:$B,"2026-07",'freee実績'!$C:$C,"広告宣伝費") -> 0 | D26: 変動費 | G26: 営業日数 | H26: 0 | U26: 営業利益率 | V26: ='売上計画'!F62 -> 0 | W26: =IF(W8=0,0,W25/W8) -> 0 | X26: =W26-V26 -> 0
B27: 修繕費 | C27: =SUMIFS('freee実績'!$E:$E,'freee実績'!$B:$B,"2026-07",'freee実績'!$C:$C,"修繕費") -> 0 | D27: 変動費 | G27: 日商（1日平均売上） | H27: =IF(H26=0,0,H20/H26) -> 0 | J27: 売上÷営業日数 | L27: ■ 人件費KPI
B28: その他経費 | C28: =SUMIFS('freee実績'!$E:$E,'freee実績'!$B:$B,"2026-07",'freee実績'!$C:$C,"雑費") -> 0 | D28: 変動費 | G28: 原価率 | H28: =IF(H20=0,0,C16/H20) -> 0 | J28: 原価÷売上 | L28: 指標 | M28: 数値 | R28: 算出方法
B29: 減価償却費 | C29: ='固定資産台帳'!O26 -> 14433.833 | D29: 帳簿上のみ | L29: 人件費率 | M29: =IF(H20=0,0,M23/H20) -> 0 | R29: 人件費÷売上
B30: 経費 合計 | C30: =SUM(C20:C29) -> 14433.833 | L30: 人時売上高 | M30: =IF((SUM(N5:N12)*SUM(O5:O12))=0,0,H20/(SUM(N5:N12)*SUM(O5:O12))) -> 0 | R30: 売上÷総労働時間
B32: ■ 一括経費（設備投資等） | G32: ■ 月次損益計算 | L32: ■ オーナー人件費 未払い管理
B33: 科目 | C33: 予算 | D33: 実績 | E33: 差額（残） | F33: メモ | H33: 項目 | I33: 金額 | L33: 帳簿上は計上、実際の支払いは利益が出てから
B34: トイレ | C34: 63900 | D34: 63900 | H34: 売上高 | I34: =H20 -> 0 | L34: 今月の人件費 支払い？ | M34: 未払い | N34: ← 「支払い」か「未払い」を入力
B35: 業務用冷蔵庫 | C35: 21890 | D35: 21890 | E35: =C35-D35 -> 0 | F35: セカスト | H35: 原価合計 | I35: =C16 -> 0 | L35: 人件費（帳簿計上額） | M35: =M23 -> 0 | N35: P/Lに反映
B36: 冷凍ストッカー | D36: 15000 | F36: セカスト | H36: 粗利益 | I36: =I34-I35 -> 0 | L36: 実際の支払い額 | M36: =IF(M34="支払い",M35,0) -> 0 | N36: 口座から出るお金
H37: 粗利率 | I37: =IF(I34=0,0,I36/I34) -> 0 | L37: 今月の未払い額 | M37: =M35-M36 -> 0 | N37: 帳簿上は経費だが現金は出ない
H38: 経費合計 | I38: =C30 -> 14433.833 | L38: 前月までの未払い累計 | M38: ='6月'!M39 -> 0
H39: 営業利益 | I39: =I36-I38 -> -14433.833 | L39: 未払い累計（今月末時点） | M39: =M38+M37 -> 0 | N39: 将来支払う必要のある額
B41: 浄水器 | D41: 45628 | E41: =C41-D41 -> -45628 | F41: EVERPURE QL3+ESO7 | L41: 過去の未払い分 今月支払額 | N41: 未払い累計から取り崩す場合に入力
B42: 2槽シンク＋手洗いシンク | D42: 50000 | E42: =C42-D42 -> -50000 | F42: 保健所要件
...

Sheet 8月
B1: ☕ カフェ経営管理 ─ 8月 | U1: ■ 計画値（売上計画シートから自動取得）
B2: 月末口座（人件費なし） | C2: =I75 -> 956398.6 | E2: 今月出ていくお金 | F2: =C16+SUM(C20:C23)+SUM(C25:C28)+M36+D54+M41 -> 2800000 | H2: 今月の利益 | I2: =I39 -> -241729.23 | L2: 来月必要なお金 | M2: ='9月'!C20+'9月'!C21+'9月'!C22+'9月'!C23+'9月'!C25 -> 0 | U2: 実績の入力時に参考にしてください。差額・達成率も自動表示。
B3: ■ 資金（期首残高） | G3: ■ 売上（定期収入） | L3: ■ 人件費計算
B4: 科目 | C4: 金額 | D4: 詳細 | E4: メモ | G4: カテゴリ | H4: 金額 | I4: 詳細 | J4: メモ | L4: スタッフ名 | M4: 時給 | N4: 日数 | O4: 時間/日 | P4: 交通費/日 | Q4: 小計（給与） | R4: 小計（交通費） | U4: ■ 売上
B5: 前月繰越金 | C5: ='7月'!I75 -> 3983694 | G5: ドリンク（コーヒー） | H5: ='8月日次売上'!C35 -> 0 | Q5: =M5*N5*O5 -> 0 | R5: =P5*N5 -> 0 | U5: 項目 | V5: 計画 | W5: 実績 | X5: 差額 | Y5: 達成率
B6: 追加資金 | E6: 融資 | G6: ドリンク（紅茶・その他） | H6: ='8月日次売上'!D35 -> 0 | Q6: =M6*N6*O6 -> 0 | R6: =P6*N6 -> 0 | U6: 昼 来客数（季節調整後）/日 | V6: ='売上計画'!G38 -> 10 | W6: =IF(H26=0,"",H24/H26/2) -> 0 | X6: =IF(W6="",0,W6-V6) -> -10 | Y6: =IF(OR(W6="",V6=0),0,W6/V6) -> 0
B7: 期首資金 合計 | C7: =SUM(C5:C6) -> 3983694 | G7: フード（軽食） | H7: ='8月日次売上'!E35 -> 0 | Q7: =M7*N7*O7 -> 0 | R7: =P7*N7 -> 0 | U7: 夜 来客数（季節調整後）/日 | V7: ='売上計画'!G39 -> 7 | W7: =IF(H26=0,"",H24/H26/2) -> 0 | X7: =IF(W7="",0,W7-V7) -> -7 | Y7: =IF(OR(W7="",V7=0),0,W7/V7) -> 0
G8: フード（スイーツ） | H8: ='8月日次売上'!F35 -> 0 | Q8: =M8*N8*O8 -> 0 | R8: =P8*N8 -> 0 | U8: 売上合計（月間） | V8: ='売上計画'!G45 -> 654100 | W8: =H20 -> 0 | X8: =W8-V8 -> -654100 | Y8: =IF(V8=0,0,W8/V8) -> 0
B9: ■ 原価（売上原価） | G9: 物販（コーヒー豆・グッズ） | H9: ='8月日次売上'!G35 -> 0 | Q9: =M9*N9*O9 -> 0 | R9: =P9*N9 -> 0 | U9: 客単価 | V9: =IF((V6*'売上計画'!$C$7+V7*'売上計画'!$C$8)=0,0,V8/(V6*'売上計画'!$C$7+V7*'売上計画'!$C$8)) -> 1282.549 | W9: =H25 -> 0 | X9: =W9-V9 -> -1282.549 | Y9: =IF(V9=0,0,W9/V9) -> 0
B10: 科目 | C10: 金額 | D10: 詳細 | E10: メモ | G10: テイクアウト | H10: ='8月日次売上'!H35 -> 0 | Q10: =M10*N10*O10 -> 0 | R10: =P10*N10 -> 0
B11: コーヒー豆・茶葉 | C11: =SUMIFS('freee実績'!$E:$E,'freee実績'!$B:$B,"2026-08",'freee実績'!$C:$C,"仕入高",'freee実績'!$D:$D,"コーヒー豆・茶葉") -> 0 | G11: 売上 合計 | H11: =SUM(H5:H10) -> 0 | Q11: =M11*N11*O11 -> 0 | R11: =P11*N11 -> 0 | U11: ■ 原価・粗利
B12: 牛乳・シロップ等 | C12: =SUMIFS('freee実績'!$E:$E,'freee実績'!$B:$B,"2026-08",'freee実績'!$C:$C,"仕入高",'freee実績'!$D:$D,"牛乳・シロップ等") -> 0 | Q12: =M12*N12*O12 -> 0 | R12: =P12*N12 -> 0 | U12: 項目 | V12: 計画 | W12: 実績 | X12: 差額 | Y12: 原価率
B13: フード材料費 | C13: =SUMIFS('freee実績'!$E:$E,'freee実績'!$B:$B,"2026-08",'freee実績'!$C:$C,"仕入高",'freee実績'!$D:$D,"フード材料費") -> 0 | G13: ■ その他収入（不定期） | L13: アルバイト給与 合計 | Q13: =SUM(Q5:Q12) -> 0 | R13: =SUM(R5:R12) -> 0 | U13: 原価合計 | V13: ='売上計画'!G46 -> 196230 | W13: =C16 -> 0 | X13: =W13-V13 -> -196230 | Y13: =IF(W8=0,0,W13/W8) -> 0
B14: 包装資材・消耗品 | C14: =SUMIFS('freee実績'!$E:$E,'freee実績'!$B:$B,"2026-08",'freee実績'!$C:$C,"仕入高",'freee実績'!$D:$D,"包装資材・消耗品") -> 0 | G14: カテゴリ | H14: 金額 | I14: 詳細 | J14: メモ | U14: 粗利益 | V14: ='売上計画'!G47 -> 457870 | W14: =H20-C16 -> 0 | X14: =W14-V14 -> -457870 | Y14: =IF(W8=0,0,W14/W8) -> 0
B15: その他原価 | C15: =SUMIFS('freee実績'!$E:$E,'freee実績'!$B:$B,"2026-08",'freee実績'!$C:$C,"仕入高",'freee実績'!$D:$D,"その他原価") -> 0 | G15: イベント・貸切 | H15: ='8月日次売上'!I35 -> 0 | L15: ■ 固定人件費（役員報酬・社員給与等）
B16: 原価 合計 | C16: =SUM(C11:C15) -> 0 | G16: その他収入② | L16: 項目 | M16: 月額 | R16: 備考 | U16: ■ 経費
G17: その他収入 | L17: 役員報酬 | U17: 項目 | V17: 計画 | W17: 実績 | X17: 差額
B18: ■ 経費（販管費） | G18: その他収入 合計 | H18: =SUM(H15:H17) -> 0 | L18: 社員給与 | U18: 人件費（バイト+固定） | V18: ='売上計画'!G54 -> 46.5 | W18: =C24 -> 227295.4 | X18: =W18-V18 -> 227248.9
B19: 科目 | C19: 金額 | D19: 詳細 | E19: メモ | L19: 社会保険料（会社負担） | U19: 固定費（家賃+光熱+通信+保険） | V19: ='売上計画'!G57 -> 644 | W19: =C20+C21+C22+C23 -> 0 | X19: =W19-V19 -> -644
B20: 家賃 | C20: =SUMIFS('freee実績'!$E:$E,'freee実績'!$B:$B,"2026-08",'freee実績'!$C:$C,"地代家賃") -> 0 | D20: 固定費 | G20: 売上合計（定期＋不定期） | H20: =H11+H18 -> 0 | L20: その他人件費 | U20: 消耗品 | V20: ='売上計画'!G58 -> 0 | W20: =C25 -> 0 | X20: =W20-V20 -> 0
B21: 水道光熱費 | C21: =SUMIFS('freee実績'!$E:$E,'freee実績'!$B:$B,"2026-08",'freee実績'!$C:$C,"水道光熱費") -> 0 | D21: 固定費 | L21: 固定人件費 合計 | M21: =SUM(M17:M20) -> 0 | U21: 経費合計 | V21: ='売上計画'!G59 -> 0 | W21: =C30 -> 241729.23 | X21: =W21-V21 -> 241729.23
B22: 通信費 | C22: =SUMIFS('freee実績'!$E:$E,'freee実績'!$B:$B,"2026-08",'freee実績'!$C:$C,"通信費") -> 0 | D22: 固定費 | G22: ■ 売上KPI
B23: 保険料 | C23: =SUMIFS('freee実績'!$E:$E,'freee実績'!$B:$B,"2026-08",'freee実績'!$C:$C,"保険料") -> 0 | D23: 固定費 | G23: 指標 | H23: 数値 | J23: 算出方法 | L23: 人件費 総合計 | M23: =Q13+R13+M21 -> 0 | U23: ■ 営業利益
B24: 人件費（給与・社保） | C24: ='役員報酬・社保'!C17+'役員報酬・社保'!E17+'役員報酬・社保'!C71+'役員報酬・社保'!E71+86400 -> 227295.4 | D24: 変動費 | G24: 来客数（人） | H24: ='8月日次売上'!J35 -> 0 | U24: 項目 | V24: 計画 | W24: 実績 | X24: 差額 | Y24: 達成率
B25: 消耗品費 | C25: =SUMIFS('freee実績'!$E:$E,'freee実績'!$B:$B,"2026-08",'freee実績'!$C:$C,"消耗品費") -> 0 | D25: 変動費 | G25: 客単価 | H25: =IF(H24=0,0,H20/H24) -> 0 | J25: 売上÷来客数 | L25: ↑ この金額を左側「人件費（給与・社保）」に転記 | U25: 営業利益 | V25: ='売上計画'!G61 | W25: =I39 -> -241729.23 | X25: =W25-V25 -> -241729.23 | Y25: =IF(V25=0,0,W25/V25) -> 0
B26: 広告宣伝費 | C26: =SUMIFS('freee実績'!$E:$E,'freee実績'!$B:$B,"2026-08",'freee実績'!$C:$C,"広告宣伝費") -> 0 | D26: 変動費 | G26: 営業日数 | H26: 31 | U26: 営業利益率 | V26: ='売上計画'!G62 -> 337870 | W26: =IF(W8=0,0,W25/W8) -> 0 | X26: =W26-V26 -> -337870
B27: 修繕費 | C27: =SUMIFS('freee実績'!$E:$E,'freee実績'!$B:$B,"2026-08",'freee実績'!$C:$C,"修繕費") -> 0 | D27: 変動費 | G27: 日商（1日平均売上） | H27: =IF(H26=0,0,H20/H26) -> 0 | J27: 売上÷営業日数 | L27: ■ 人件費KPI
B28: その他経費 | C28: =SUMIFS('freee実績'!$E:$E,'freee実績'!$B:$B,"2026-08",'freee実績'!$C:$C,"雑費") -> 0 | D28: 変動費 | G28: 原価率 | H28: =IF(H20=0,0,C16/H20) -> 0 | J28: 原価÷売上 | L28: 指標 | M28: 数値 | R28: 算出方法
B29: 減価償却費 | C29: ='固定資産台帳'!P26 -> 14433.833 | D29: 帳簿上のみ | L29: 人件費率 | M29: =IF(H20=0,0,M23/H20) -> 0 | R29: 人件費÷売上
B30: 経費 合計 | C30: =SUM(C20:C29) -> 241729.23 | L30: 人時売上高 | M30: =IF((SUM(N5:N12)*SUM(O5:O12))=0,0,H20/(SUM(N5:N12)*SUM(O5:O12))) -> 0 | R30: 売上÷総労働時間
B32: ■ 一括経費（設備投資等） | G32: ■ 月次損益計算 | L32: ■ オーナー人件費 未払い管理
B33: 科目 | C33: 予算 | D33: 実績 | E33: 差額（残） | F33: メモ | H33: 項目 | I33: 金額 | L33: 帳簿上は計上、実際の支払いは利益が出てから
B34: 設備購入 | E34: =C34-D34 -> 0 | H34: 売上高 | I34: =H20 -> 0 | L34: 今月の人件費 支払い？ | M34: 未払い | N34: ← 「支払い」か「未払い」を入力
B35: 内装工事 | C35: 2800000 | D35: 2800000 | E35: =C35-D35 -> 0 | H35: 原価合計 | I35: =C16 -> 0 | L35: 人件費（帳簿計上額） | M35: =M23 -> 0 | N35: P/Lに反映
B36: その他一括経費 | E36: =C36-D36 -> 0 | H36: 粗利益 | I36: =I34-I35 -> 0 | L36: 実際の支払い額 | M36: =IF(M34="支払い",M35,0) -> 0 | N36: 口座から出るお金
E37: =C37-D37 -> 0 | H37: 粗利率 | I37: =IF(I34=0,0,I36/I34) -> 0 | L37: 今月の未払い額 | M37: =M35-M36 -> 0 | N37: 帳簿上は経費だが現金は出ない
E38: =C38-D38 -> 0 | H38: 経費合計 | I38: =C30 -> 241729.23 | L38: 前月までの未払い累計 | M38: ='7月'!M39 -> 0
E39: =C39-D39 -> 0 | H39: 営業利益 | I39: =I36-I38 -> -241729.23 | L39: 未払い累計（今月末時点） | M39: =M38+M37 -> 0 | N39: 将来支払う必要のある額
E40: =C40-D40 -> 0
E41: =C41-D41 -> 0 | L41: 過去の未払い分 今月支払額 | N41: 未払い累計から取り崩す場合に入力
...

Sheet 9月
B1: ☕ カフェ経営管理 ─ 9月 | U1: ■ 計画値（売上計画シートから自動取得）
B2: 月末口座（人件費なし） | C2: =I75 -> 1729103.2 | E2: 今月出ていくお金 | F2: =C16+SUM(C20:C23)+SUM(C25:C28)+M36+D54+M41 -> 0 | H2: 今月の利益 | I2: =I39 -> -241729.23 | L2: 来月必要なお金 | M2: ='10月'!C20+'10月'!C21+'10月'!C22+'10月'!C23+'10月'!C25 -> 0 | U2: 実績の入力時に参考にしてください。差額・達成率も自動表示。
B3: ■ 資金（期首残高） | G3: ■ 売上（定期収入） | L3: ■ 人件費計算
B4: 科目 | C4: 金額 | D4: 詳細 | E4: メモ | G4: カテゴリ | H4: 金額 | I4: 詳細 | J4: メモ | L4: スタッフ名 | M4: 時給 | N4: 日数 | O4: 時間/日 | P4: 交通費/日 | Q4: 小計（給与） | R4: 小計（交通費） | U4: ■ 売上
B5: 前月繰越金 | C5: ='8月'!I75 -> 956398.6 | G5: ドリンク（コーヒー） | H5: ='9月日次売上'!C34 -> 0 | Q5: =M5*N5*O5 -> 0 | R5: =P5*N5 -> 0 | U5: 項目 | V5: 計画 | W5: 実績 | X5: 差額 | Y5: 達成率
B6: 追加資金（借入等） | C6: 1000000 | D6: クラウドファンディング | E6: クラファン100万円入金（9月） | G6: ドリンク（紅茶・その他） | H6: ='9月日次売上'!D34 -> 0 | Q6: =M6*N6*O6 -> 0 | R6: =P6*N6 -> 0 | U6: 昼 来客数（季節調整後）/日 | V6: ='売上計画'!H38 -> 13 | W6: =IF(H26=0,"",H24/H26/2) -> 0 | X6: =IF(W6="",0,W6-V6) -> -13 | Y6: =IF(OR(W6="",V6=0),0,W6/V6) -> 0
B7: 期首資金 合計 | C7: =SUM(C5:C6) -> 1956398.6 | G7: フード（軽食） | H7: ='9月日次売上'!E34 -> 0 | Q7: =M7*N7*O7 -> 0 | R7: =P7*N7 -> 0 | U7: 夜 来客数（季節調整後）/日 | V7: ='売上計画'!H39 -> 7 | W7: =IF(H26=0,"",H24/H26/2) -> 0 | X7: =IF(W7="",0,W7-V7) -> -7 | Y7: =IF(OR(W7="",V7=0),0,W7/V7) -> 0
G8: フード（スイーツ） | H8: ='9月日次売上'!F34 -> 0 | Q8: =M8*N8*O8 -> 0 | R8: =P8*N8 -> 0 | U8: 売上合計（月間） | V8: ='売上計画'!H45 -> 709500 | W8: =H20 -> 0 | X8: =W8-V8 -> -709500 | Y8: =IF(V8=0,0,W8/V8) -> 0
B9: ■ 原価（売上原価） | G9: 物販（コーヒー豆・グッズ） | H9: ='9月日次売上'!G34 -> 0 | Q9: =M9*N9*O9 -> 0 | R9: =P9*N9 -> 0 | U9: 客単価 | V9: =IF((V6*'売上計画'!$C$7+V7*'売上計画'!$C$8)=0,0,V8/(V6*'売上計画'!$C$7+V7*'売上計画'!$C$8)) -> 1182.5 | W9: =H25 -> 0 | X9: =W9-V9 -> -1182.5 | Y9: =IF(V9=0,0,W9/V9) -> 0
B10: 科目 | C10: 金額 | D10: 詳細 | E10: メモ | G10: テイクアウト | H10: ='9月日次売上'!H34 -> 0 | Q10: =M10*N10*O10 -> 0 | R10: =P10*N10 -> 0
B11: コーヒー豆・茶葉 | C11: =SUMIFS('freee実績'!$E:$E,'freee実績'!$B:$B,"2026-09",'freee実績'!$C:$C,"仕入高",'freee実績'!$D:$D,"コーヒー豆・茶葉") -> 0 | G11: 売上 合計 | H11: =SUM(H5:H10) -> 0 | Q11: =M11*N11*O11 -> 0 | R11: =P11*N11 -> 0 | U11: ■ 原価・粗利
B12: 牛乳・シロップ等 | C12: =SUMIFS('freee実績'!$E:$E,'freee実績'!$B:$B,"2026-09",'freee実績'!$C:$C,"仕入高",'freee実績'!$D:$D,"牛乳・シロップ等") -> 0 | Q12: =M12*N12*O12 -> 0 | R12: =P12*N12 -> 0 | U12: 項目 | V12: 計画 | W12: 実績 | X12: 差額 | Y12: 原価率
B13: フード材料費 | C13: =SUMIFS('freee実績'!$E:$E,'freee実績'!$B:$B,"2026-09",'freee実績'!$C:$C,"仕入高",'freee実績'!$D:$D,"フード材料費") -> 0 | G13: ■ その他収入（不定期） | L13: アルバイト給与 合計 | Q13: =SUM(Q5:Q12) -> 0 | R13: =SUM(R5:R12) -> 0 | U13: 原価合計 | V13: ='売上計画'!H46 -> 212850 | W13: =C16 -> 0 | X13: =W13-V13 -> -212850 | Y13: =IF(W8=0,0,W13/W8) -> 0
B14: 包装資材・消耗品 | C14: =SUMIFS('freee実績'!$E:$E,'freee実績'!$B:$B,"2026-09",'freee実績'!$C:$C,"仕入高",'freee実績'!$D:$D,"包装資材・消耗品") -> 0 | G14: カテゴリ | H14: 金額 | I14: 詳細 | J14: メモ | U14: 粗利益 | V14: ='売上計画'!H47 -> 496650 | W14: =H20-C16 -> 0 | X14: =W14-V14 -> -496650 | Y14: =IF(W8=0,0,W14/W8) -> 0
B15: その他原価 | C15: =SUMIFS('freee実績'!$E:$E,'freee実績'!$B:$B,"2026-09",'freee実績'!$C:$C,"仕入高",'freee実績'!$D:$D,"その他原価") -> 0 | G15: イベント・貸切 | H15: ='9月日次売上'!I34 -> 0 | L15: ■ 固定人件費（役員報酬・社員給与等）
B16: 原価 合計 | C16: =SUM(C11:C15) -> 0 | G16: その他収入② | L16: 項目 | M16: 月額 | R16: 備考 | U16: ■ 経費
G17: その他収入 | L17: 役員報酬 | U17: 項目 | V17: 計画 | W17: 実績 | X17: 差額
B18: ■ 経費（販管費） | G18: その他収入 合計 | H18: =SUM(H15:H17) -> 0 | L18: 社員給与 | U18: 人件費（バイト+固定） | V18: ='売上計画'!H54 -> 45 | W18: =C24 -> 227295.4 | X18: =W18-V18 -> 227250.4
B19: 科目 | C19: 金額 | D19: 詳細 | E19: メモ | L19: 社会保険料（会社負担） | U19: 固定費（家賃+光熱+通信+保険） | V19: ='売上計画'!H57 -> 570 | W19: =C20+C21+C22+C23 -> 0 | X19: =W19-V19 -> -570
B20: 家賃 | C20: =SUMIFS('freee実績'!$E:$E,'freee実績'!$B:$B,"2026-09",'freee実績'!$C:$C,"地代家賃") -> 0 | D20: 固定費 | G20: 売上合計（定期＋不定期） | H20: =H11+H18 -> 0 | L20: その他人件費 | U20: 消耗品 | V20: ='売上計画'!H58 -> 0 | W20: =C25 -> 0 | X20: =W20-V20 -> 0
B21: 水道光熱費 | C21: =SUMIFS('freee実績'!$E:$E,'freee実績'!$B:$B,"2026-09",'freee実績'!$C:$C,"水道光熱費") -> 0 | D21: 固定費 | L21: 固定人件費 合計 | M21: =SUM(M17:M20) -> 0 | U21: 経費合計 | V21: ='売上計画'!H59 -> 0 | W21: =C30 -> 241729.23 | X21: =W21-V21 -> 241729.23
B22: 通信費 | C22: =SUMIFS('freee実績'!$E:$E,'freee実績'!$B:$B,"2026-09",'freee実績'!$C:$C,"通信費") -> 0 | D22: 固定費 | G22: ■ 売上KPI
B23: 保険料 | C23: =SUMIFS('freee実績'!$E:$E,'freee実績'!$B:$B,"2026-09",'freee実績'!$C:$C,"保険料") -> 0 | D23: 固定費 | G23: 指標 | H23: 数値 | J23: 算出方法 | L23: 人件費 総合計 | M23: =Q13+R13+M21 -> 0 | U23: ■ 営業利益
B24: 人件費（給与・社保） | C24: ='役員報酬・社保'!C17+'役員報酬・社保'!E17+'役員報酬・社保'!C71+'役員報酬・社保'!E71+86400 -> 227295.4 | D24: 変動費 | G24: 来客数（人） | H24: ='9月日次売上'!J34 -> 0 | U24: 項目 | V24: 計画 | W24: 実績 | X24: 差額 | Y24: 達成率
B25: 消耗品費 | C25: =SUMIFS('freee実績'!$E:$E,'freee実績'!$B:$B,"2026-09",'freee実績'!$C:$C,"消耗品費") -> 0 | D25: 変動費 | G25: 客単価 | H25: =IF(H24=0,0,H20/H24) -> 0 | J25: 売上÷来客数 | L25: ↑ この金額を左側「人件費（給与・社保）」に転記 | U25: 営業利益 | V25: ='売上計画'!H61 | W25: =I39 -> -241729.23 | X25: =W25-V25 -> -241729.23 | Y25: =IF(V25=0,0,W25/V25) -> 0
B26: 広告宣伝費 | C26: =SUMIFS('freee実績'!$E:$E,'freee実績'!$B:$B,"2026-09",'freee実績'!$C:$C,"広告宣伝費") -> 0 | D26: 変動費 | G26: 営業日数 | H26: 30 | U26: 営業利益率 | V26: ='売上計画'!H62 -> 316650 | W26: =IF(W8=0,0,W25/W8) -> 0 | X26: =W26-V26 -> -316650
B27: 修繕費 | C27: =SUMIFS('freee実績'!$E:$E,'freee実績'!$B:$B,"2026-09",'freee実績'!$C:$C,"修繕費") -> 0 | D27: 変動費 | G27: 日商（1日平均売上） | H27: =IF(H26=0,0,H20/H26) -> 0 | J27: 売上÷営業日数 | L27: ■ 人件費KPI
B28: その他経費 | C28: =SUMIFS('freee実績'!$E:$E,'freee実績'!$B:$B,"2026-09",'freee実績'!$C:$C,"雑費") -> 0 | D28: 変動費 | G28: 原価率 | H28: =IF(H20=0,0,C16/H20) -> 0 | J28: 原価÷売上 | L28: 指標 | M28: 数値 | R28: 算出方法
B29: 減価償却費 | C29: ='固定資産台帳'!Q26 -> 14433.833 | D29: 帳簿上のみ | L29: 人件費率 | M29: =IF(H20=0,0,M23/H20) -> 0 | R29: 人件費÷売上
B30: 経費 合計 | C30: =SUM(C20:C29) -> 241729.23 | L30: 人時売上高 | M30: =IF((SUM(N5:N12)*SUM(O5:O12))=0,0,H20/(SUM(N5:N12)*SUM(O5:O12))) -> 0 | R30: 売上÷総労働時間
B32: ■ 一括経費（設備投資等） | G32: ■ 月次損益計算 | L32: ■ オーナー人件費 未払い管理
B33: 科目 | C33: 予算 | D33: 実績 | E33: 差額（残） | F33: メモ | H33: 項目 | I33: 金額 | L33: 帳簿上は計上、実際の支払いは利益が出てから
B34: 設備購入 | E34: =C34-D34 -> 0 | H34: 売上高 | I34: =H20 -> 0 | L34: 今月の人件費 支払い？ | M34: 未払い | N34: ← 「支払い」か「未払い」を入力
B35: 内装工事 | E35: =C35-D35 -> 0 | H35: 原価合計 | I35: =C16 -> 0 | L35: 人件費（帳簿計上額） | M35: =M23 -> 0 | N35: P/Lに反映
B36: その他一括経費 | E36: =C36-D36 -> 0 | H36: 粗利益 | I36: =I34-I35 -> 0 | L36: 実際の支払い額 | M36: =IF(M34="支払い",M35,0) -> 0 | N36: 口座から出るお金
E37: =C37-D37 -> 0 | H37: 粗利率 | I37: =IF(I34=0,0,I36/I34) -> 0 | L37: 今月の未払い額 | M37: =M35-M36 -> 0 | N37: 帳簿上は経費だが現金は出ない
E38: =C38-D38 -> 0 | H38: 経費合計 | I38: =C30 -> 241729.23 | L38: 前月までの未払い累計 | M38: ='8月'!M39 -> 0
E39: =C39-D39 -> 0 | H39: 営業利益 | I39: =I36-I38 -> -241729.23 | L39: 未払い累計（今月末時点） | M39: =M38+M37 -> 0 | N39: 将来支払う必要のある額
E40: =C40-D40 -> 0
E41: =C41-D41 -> 0 | L41: 過去の未払い分 今月支払額 | N41: 未払い累計から取り崩す場合に入力
...

Sheet 10月
B1: ☕ カフェ経営管理 ─ 10月 | U1: ■ 計画値（売上計画シートから自動取得）
B2: 月末口座（人件費なし） | C2: =I75 -> 1431360.1 | E2: 今月出ていくお金 | F2: =C16+SUM(C20:C23)+SUM(C25:C28)+M36+D54+M41 -> 0 | H2: 今月の利益 | I2: =I39 -> -312176.93 | L2: 来月必要なお金 | M2: ='11月'!C20+'11月'!C21+'11月'!C22+'11月'!C23+'11月'!C25 -> 0 | U2: 実績の入力時に参考にしてください。差額・達成率も自動表示。
B3: ■ 資金（期首残高） | G3: ■ 売上（定期収入） | L3: ■ 人件費計算
B4: 科目 | C4: 金額 | D4: 詳細 | E4: メモ | G4: カテゴリ | H4: 金額 | I4: 詳細 | J4: メモ | L4: スタッフ名 | M4: 時給 | N4: 日数 | O4: 時間/日 | P4: 交通費/日 | Q4: 小計（給与） | R4: 小計（交通費） | U4: ■ 売上
B5: 前月繰越金 | C5: ='9月'!I75 -> 1729103.2 | G5: ドリンク（コーヒー） | H5: ='10月日次売上'!C35 -> 0 | Q5: =M5*N5*O5 -> 0 | R5: =P5*N5 -> 0 | U5: 項目 | V5: 計画 | W5: 実績 | X5: 差額 | Y5: 達成率
B6: 追加資金（借入等） | G6: ドリンク（紅茶・その他） | H6: ='10月日次売上'!D35 -> 0 | Q6: =M6*N6*O6 -> 0 | R6: =P6*N6 -> 0 | U6: 昼 来客数（季節調整後）/日 | V6: ='売上計画'!I38 -> 16 | W6: =IF(H26=0,"",H24/H26/2) -> 0 | X6: =IF(W6="",0,W6-V6) -> -16 | Y6: =IF(OR(W6="",V6=0),0,W6/V6) -> 0
B7: 期首資金 合計 | C7: =SUM(C5:C6) -> 1729103.2 | G7: フード（軽食） | H7: ='10月日次売上'!E35 -> 0 | Q7: =M7*N7*O7 -> 0 | R7: =P7*N7 -> 0 | U7: 夜 来客数（季節調整後）/日 | V7: ='売上計画'!I39 -> 12 | W7: =IF(H26=0,"",H24/H26/2) -> 0 | X7: =IF(W7="",0,W7-V7) -> -12 | Y7: =IF(OR(W7="",V7=0),0,W7/V7) -> 0
G8: フード（スイーツ） | H8: ='10月日次売上'!F35 -> 0 | Q8: =M8*N8*O8 -> 0 | R8: =P8*N8 -> 0 | U8: 売上合計（月間） | V8: ='売上計画'!I45 -> 1091200 | W8: =H20 -> 0 | X8: =W8-V8 -> -1091200 | Y8: =IF(V8=0,0,W8/V8) -> 0
B9: ■ 原価（売上原価） | G9: 物販（コーヒー豆・グッズ） | H9: ='10月日次売上'!G35 -> 0 | Q9: =M9*N9*O9 -> 0 | R9: =P9*N9 -> 0 | U9: 客単価 | V9: =IF((V6*'売上計画'!$C$7+V7*'売上計画'!$C$8)=0,0,V8/(V6*'売上計画'!$C$7+V7*'売上計画'!$C$8)) -> 1299.0476 | W9: =H25 -> 0 | X9: =W9-V9 -> -1299.0476 | Y9: =IF(V9=0,0,W9/V9) -> 0
B10: 科目 | C10: 金額 | D10: 詳細 | E10: メモ | G10: テイクアウト | H10: ='10月日次売上'!H35 -> 0 | Q10: =M10*N10*O10 -> 0 | R10: =P10*N10 -> 0
B11: コーヒー豆・茶葉 | C11: =SUMIFS('freee実績'!$E:$E,'freee実績'!$B:$B,"2026-10",'freee実績'!$C:$C,"仕入高",'freee実績'!$D:$D,"コーヒー豆・茶葉") -> 0 | G11: 売上 合計 | H11: =SUM(H5:H10) -> 0 | Q11: =M11*N11*O11 -> 0 | R11: =P11*N11 -> 0 | U11: ■ 原価・粗利
B12: 牛乳・シロップ等 | C12: =SUMIFS('freee実績'!$E:$E,'freee実績'!$B:$B,"2026-10",'freee実績'!$C:$C,"仕入高",'freee実績'!$D:$D,"牛乳・シロップ等") -> 0 | Q12: =M12*N12*O12 -> 0 | R12: =P12*N12 -> 0 | U12: 項目 | V12: 計画 | W12: 実績 | X12: 差額 | Y12: 原価率
B13: フード材料費 | C13: =SUMIFS('freee実績'!$E:$E,'freee実績'!$B:$B,"2026-10",'freee実績'!$C:$C,"仕入高",'freee実績'!$D:$D,"フード材料費") -> 0 | G13: ■ その他収入（不定期） | L13: アルバイト給与 合計 | Q13: =SUM(Q5:Q12) -> 0 | R13: =SUM(R5:R12) -> 0 | U13: 原価合計 | V13: ='売上計画'!I46 -> 327360 | W13: =C16 -> 0 | X13: =W13-V13 -> -327360 | Y13: =IF(W8=0,0,W13/W8) -> 0
B14: 包装資材・消耗品 | C14: =SUMIFS('freee実績'!$E:$E,'freee実績'!$B:$B,"2026-10",'freee実績'!$C:$C,"仕入高",'freee実績'!$D:$D,"包装資材・消耗品") -> 0 | G14: カテゴリ | H14: 金額 | I14: 詳細 | J14: メモ | U14: 粗利益 | V14: ='売上計画'!I47 -> 763840 | W14: =H20-C16 -> 0 | X14: =W14-V14 -> -763840 | Y14: =IF(W8=0,0,W14/W8) -> 0
B15: その他原価 | C15: =SUMIFS('freee実績'!$E:$E,'freee実績'!$B:$B,"2026-10",'freee実績'!$C:$C,"仕入高",'freee実績'!$D:$D,"その他原価") -> 0 | G15: イベント・貸切 | H15: ='10月日次売上'!I35 -> 0 | L15: ■ 固定人件費（役員報酬・社員給与等）
B16: 原価 合計 | C16: =SUM(C11:C15) -> 0 | G16: その他収入② | L16: 項目 | M16: 月額 | R16: 備考 | U16: ■ 経費
G17: その他収入 | L17: 役員報酬 | U17: 項目 | V17: 計画 | W17: 実績 | X17: 差額
B18: ■ 経費（販管費） | G18: その他収入 合計 | H18: =SUM(H15:H17) -> 0 | L18: 社員給与 | U18: 人件費（バイト+固定） | V18: ='売上計画'!I54 -> 46.5 | W18: =C24 -> 297743.1 | X18: =W18-V18 -> 297696.6
B19: 科目 | C19: 金額 | D19: 詳細 | E19: メモ | L19: 社会保険料（会社負担） | U19: 固定費（家賃+光熱+通信+保険） | V19: ='売上計画'!I57 -> 544 | W19: =C20+C21+C22+C23 -> 0 | X19: =W19-V19 -> -544
B20: 家賃 | C20: =SUMIFS('freee実績'!$E:$E,'freee実績'!$B:$B,"2026-10",'freee実績'!$C:$C,"地代家賃") -> 0 | D20: 固定費 | G20: 売上合計（定期＋不定期） | H20: =H11+H18 -> 0 | L20: その他人件費 | U20: 消耗品 | V20: ='売上計画'!I58 -> 0 | W20: =C25 -> 0 | X20: =W20-V20 -> 0
B21: 水道光熱費 | C21: =SUMIFS('freee実績'!$E:$E,'freee実績'!$B:$B,"2026-10",'freee実績'!$C:$C,"水道光熱費") -> 0 | D21: 固定費 | L21: 固定人件費 合計 | M21: =SUM(M17:M20) -> 0 | U21: 経費合計 | V21: ='売上計画'!I59 -> 0 | W21: =C30 -> 312176.93 | X21: =W21-V21 -> 312176.93
B22: 通信費 | C22: =SUMIFS('freee実績'!$E:$E,'freee実績'!$B:$B,"2026-10",'freee実績'!$C:$C,"通信費") -> 0 | D22: 固定費 | G22: ■ 売上KPI
B23: 保険料 | C23: =SUMIFS('freee実績'!$E:$E,'freee実績'!$B:$B,"2026-10",'freee実績'!$C:$C,"保険料") -> 0 | D23: 固定費 | G23: 指標 | H23: 数値 | J23: 算出方法 | L23: 人件費 総合計 | M23: =Q13+R13+M21 -> 0 | U23: ■ 営業利益
B24: 人件費（給与・社保） | C24: ='役員報酬・社保'!C17+'役員報酬・社保'!D17+'役員報酬・社保'!E17+'役員報酬・社保'!F71+86400 -> 297743.1 | D24: 変動費 | G24: 来客数（人） | H24: ='10月日次売上'!J35 -> 0 | U24: 項目 | V24: 計画 | W24: 実績 | X24: 差額 | Y24: 達成率
B25: 消耗品費 | C25: =SUMIFS('freee実績'!$E:$E,'freee実績'!$B:$B,"2026-10",'freee実績'!$C:$C,"消耗品費") -> 0 | D25: 変動費 | G25: 客単価 | H25: =IF(H24=0,0,H20/H24) -> 0 | J25: 売上÷来客数 | L25: ↑ この金額を左側「人件費（給与・社保）」に転記 | U25: 営業利益 | V25: ='売上計画'!I61 | W25: =I39 -> -312176.93 | X25: =W25-V25 -> -312176.93 | Y25: =IF(V25=0,0,W25/V25) -> 0
B26: 広告宣伝費 | C26: =SUMIFS('freee実績'!$E:$E,'freee実績'!$B:$B,"2026-10",'freee実績'!$C:$C,"広告宣伝費") -> 0 | D26: 変動費 | G26: 営業日数 | H26: 31 | U26: 営業利益率 | V26: ='売上計画'!I62 -> 523840 | W26: =IF(W8=0,0,W25/W8) -> 0 | X26: =W26-V26 -> -523840
B27: 修繕費 | C27: =SUMIFS('freee実績'!$E:$E,'freee実績'!$B:$B,"2026-10",'freee実績'!$C:$C,"修繕費") -> 0 | D27: 変動費 | G27: 日商（1日平均売上） | H27: =IF(H26=0,0,H20/H26) -> 0 | J27: 売上÷営業日数 | L27: ■ 人件費KPI
B28: その他経費 | C28: =SUMIFS('freee実績'!$E:$E,'freee実績'!$B:$B,"2026-10",'freee実績'!$C:$C,"雑費") -> 0 | D28: 変動費 | G28: 原価率 | H28: =IF(H20=0,0,C16/H20) -> 0 | J28: 原価÷売上 | L28: 指標 | M28: 数値 | R28: 算出方法
B29: 減価償却費 | C29: ='固定資産台帳'!R26 -> 14433.833 | D29: 帳簿上のみ | L29: 人件費率 | M29: =IF(H20=0,0,M23/H20) -> 0 | R29: 人件費÷売上
B30: 経費 合計 | C30: =SUM(C20:C29) -> 312176.93 | L30: 人時売上高 | M30: =IF((SUM(N5:N12)*SUM(O5:O12))=0,0,H20/(SUM(N5:N12)*SUM(O5:O12))) -> 0 | R30: 売上÷総労働時間
B32: ■ 一括経費（設備投資等） | G32: ■ 月次損益計算 | L32: ■ オーナー人件費 未払い管理
B33: 科目 | C33: 予算 | D33: 実績 | E33: 差額（残） | F33: メモ | H33: 項目 | I33: 金額 | L33: 帳簿上は計上、実際の支払いは利益が出てから
B34: 設備購入 | E34: =C34-D34 -> 0 | H34: 売上高 | I34: =H20 -> 0 | L34: 今月の人件費 支払い？ | M34: 未払い | N34: ← 「支払い」か「未払い」を入力
B35: 内装工事 | E35: =C35-D35 -> 0 | H35: 原価合計 | I35: =C16 -> 0 | L35: 人件費（帳簿計上額） | M35: =M23 -> 0 | N35: P/Lに反映
B36: その他一括経費 | E36: =C36-D36 -> 0 | H36: 粗利益 | I36: =I34-I35 -> 0 | L36: 実際の支払い額 | M36: =IF(M34="支払い",M35,0) -> 0 | N36: 口座から出るお金
E37: =C37-D37 -> 0 | H37: 粗利率 | I37: =IF(I34=0,0,I36/I34) -> 0 | L37: 今月の未払い額 | M37: =M35-M36 -> 0 | N37: 帳簿上は経費だが現金は出ない
E38: =C38-D38 -> 0 | H38: 経費合計 | I38: =C30 -> 312176.93 | L38: 前月までの未払い累計 | M38: ='9月'!M39 -> 0
E39: =C39-D39 -> 0 | H39: 営業利益 | I39: =I36-I38 -> -312176.93 | L39: 未払い累計（今月末時点） | M39: =M38+M37 -> 0 | N39: 将来支払う必要のある額
E40: =C40-D40 -> 0
E41: =C41-D41 -> 0 | L41: 過去の未払い分 今月支払額 | N41: 未払い累計から取り崩す場合に入力
...

Sheet 11月
B1: ☕ カフェ経営管理 ─ 11月 | U1: ■ 計画値（売上計画シートから自動取得）
B2: 月末口座（人件費なし） | C2: =I75 -> 1133617 | E2: 今月出ていくお金 | F2: =C16+SUM(C20:C23)+SUM(C25:C28)+M36+D54+M41 -> 0 | H2: 今月の利益 | I2: =I39 -> -312176.93 | L2: 来月必要なお金 | M2: ='12月'!C20+'12月'!C21+'12月'!C22+'12月'!C23+'12月'!C25 -> 0 | U2: 実績の入力時に参考にしてください。差額・達成率も自動表示。
B3: ■ 資金（期首残高） | G3: ■ 売上（定期収入） | L3: ■ 人件費計算
B4: 科目 | C4: 金額 | D4: 詳細 | E4: メモ | G4: カテゴリ | H4: 金額 | I4: 詳細 | J4: メモ | L4: スタッフ名 | M4: 時給 | N4: 日数 | O4: 時間/日 | P4: 交通費/日 | Q4: 小計（給与） | R4: 小計（交通費） | U4: ■ 売上
B5: 前月繰越金 | C5: ='10月'!I75 -> 1431360.1 | G5: ドリンク（コーヒー） | H5: ='11月日次売上'!C34 -> 0 | Q5: =M5*N5*O5 -> 0 | R5: =P5*N5 -> 0 | U5: 項目 | V5: 計画 | W5: 実績 | X5: 差額 | Y5: 達成率
B6: 追加資金（借入等） | G6: ドリンク（紅茶・その他） | H6: ='11月日次売上'!D34 -> 0 | Q6: =M6*N6*O6 -> 0 | R6: =P6*N6 -> 0 | U6: 昼 来客数（季節調整後）/日 | V6: ='売上計画'!J38 -> 26 | W6: =IF(H26=0,"",H24/H26/2) -> 0 | X6: =IF(W6="",0,W6-V6) -> -26 | Y6: =IF(OR(W6="",V6=0),0,W6/V6) -> 0
B7: 期首資金 合計 | C7: =SUM(C5:C6) -> 1431360.1 | G7: フード（軽食） | H7: ='11月日次売上'!E34 -> 0 | Q7: =M7*N7*O7 -> 0 | R7: =P7*N7 -> 0 | U7: 夜 来客数（季節調整後）/日 | V7: ='売上計画'!J39 -> 16 | W7: =IF(H26=0,"",H24/H26/2) -> 0 | X7: =IF(W7="",0,W7-V7) -> -16 | Y7: =IF(OR(W7="",V7=0),0,W7/V7) -> 0
G8: フード（スイーツ） | H8: ='11月日次売上'!F34 -> 0 | Q8: =M8*N8*O8 -> 0 | R8: =P8*N8 -> 0 | U8: 売上合計（月間） | V8: ='売上計画'!J45 -> 1527000 | W8: =H20 -> 0 | X8: =W8-V8 -> -1527000 | Y8: =IF(V8=0,0,W8/V8) -> 0
B9: ■ 原価（売上原価） | G9: 物販（コーヒー豆・グッズ） | H9: ='11月日次売上'!G34 -> 0 | Q9: =M9*N9*O9 -> 0 | R9: =P9*N9 -> 0 | U9: 客単価 | V9: =IF((V6*'売上計画'!$C$7+V7*'売上計画'!$C$8)=0,0,V8/(V6*'売上計画'!$C$7+V7*'売上計画'!$C$8)) -> 1211.9048 | W9: =H25 -> 0 | X9: =W9-V9 -> -1211.9048 | Y9: =IF(V9=0,0,W9/V9) -> 0
B10: 科目 | C10: 金額 | D10: 詳細 | E10: メモ | G10: テイクアウト | H10: ='11月日次売上'!H34 -> 0 | Q10: =M10*N10*O10 -> 0 | R10: =P10*N10 -> 0
B11: コーヒー豆・茶葉 | C11: =SUMIFS('freee実績'!$E:$E,'freee実績'!$B:$B,"2026-11",'freee実績'!$C:$C,"仕入高",'freee実績'!$D:$D,"コーヒー豆・茶葉") -> 0 | G11: 売上 合計 | H11: =SUM(H5:H10) -> 0 | Q11: =M11*N11*O11 -> 0 | R11: =P11*N11 -> 0 | U11: ■ 原価・粗利
B12: 牛乳・シロップ等 | C12: =SUMIFS('freee実績'!$E:$E,'freee実績'!$B:$B,"2026-11",'freee実績'!$C:$C,"仕入高",'freee実績'!$D:$D,"牛乳・シロップ等") -> 0 | Q12: =M12*N12*O12 -> 0 | R12: =P12*N12 -> 0 | U12: 項目 | V12: 計画 | W12: 実績 | X12: 差額 | Y12: 原価率
B13: フード材料費 | C13: =SUMIFS('freee実績'!$E:$E,'freee実績'!$B:$B,"2026-11",'freee実績'!$C:$C,"仕入高",'freee実績'!$D:$D,"フード材料費") -> 0 | G13: ■ その他収入（不定期） | L13: アルバイト給与 合計 | Q13: =SUM(Q5:Q12) -> 0 | R13: =SUM(R5:R12) -> 0 | U13: 原価合計 | V13: ='売上計画'!J46 -> 458100 | W13: =C16 -> 0 | X13: =W13-V13 -> -458100 | Y13: =IF(W8=0,0,W13/W8) -> 0
B14: 包装資材・消耗品 | C14: =SUMIFS('freee実績'!$E:$E,'freee実績'!$B:$B,"2026-11",'freee実績'!$C:$C,"仕入高",'freee実績'!$D:$D,"包装資材・消耗品") -> 0 | G14: カテゴリ | H14: 金額 | I14: 詳細 | J14: メモ | U14: 粗利益 | V14: ='売上計画'!J47 -> 1068900 | W14: =H20-C16 -> 0 | X14: =W14-V14 -> -1068900 | Y14: =IF(W8=0,0,W14/W8) -> 0
B15: その他原価 | C15: =SUMIFS('freee実績'!$E:$E,'freee実績'!$B:$B,"2026-11",'freee実績'!$C:$C,"仕入高",'freee実績'!$D:$D,"その他原価") -> 0 | G15: イベント・貸切 | H15: ='11月日次売上'!I34 -> 0 | L15: ■ 固定人件費（役員報酬・社員給与等）
B16: 原価 合計 | C16: =SUM(C11:C15) -> 0 | G16: その他収入② | L16: 項目 | M16: 月額 | R16: 備考 | U16: ■ 経費
G17: その他収入 | L17: 役員報酬 | U17: 項目 | V17: 計画 | W17: 実績 | X17: 差額
B18: ■ 経費（販管費） | G18: その他収入 合計 | H18: =SUM(H15:H17) -> 0 | L18: 社員給与 | U18: 人件費（バイト+固定） | V18: ='売上計画'!J54 -> 45 | W18: =C24 -> 297743.1 | X18: =W18-V18 -> 297698.1
B19: 科目 | C19: 金額 | D19: 詳細 | E19: メモ | L19: 社会保険料（会社負担） | U19: 固定費（家賃+光熱+通信+保険） | V19: ='売上計画'!J57 -> 605 | W19: =C20+C21+C22+C23 -> 0 | X19: =W19-V19 -> -605
B20: 家賃 | C20: =SUMIFS('freee実績'!$E:$E,'freee実績'!$B:$B,"2026-11",'freee実績'!$C:$C,"地代家賃") -> 0 | D20: 固定費 | G20: 売上合計（定期＋不定期） | H20: =H11+H18 -> 0 | L20: その他人件費 | U20: 消耗品 | V20: ='売上計画'!J58 -> 0 | W20: =C25 -> 0 | X20: =W20-V20 -> 0
B21: 水道光熱費 | C21: =SUMIFS('freee実績'!$E:$E,'freee実績'!$B:$B,"2026-11",'freee実績'!$C:$C,"水道光熱費") -> 0 | D21: 固定費 | L21: 固定人件費 合計 | M21: =SUM(M17:M20) -> 0 | U21: 経費合計 | V21: ='売上計画'!J59 -> 0 | W21: =C30 -> 312176.93 | X21: =W21-V21 -> 312176.93
B22: 通信費 | C22: =SUMIFS('freee実績'!$E:$E,'freee実績'!$B:$B,"2026-11",'freee実績'!$C:$C,"通信費") -> 0 | D22: 固定費 | G22: ■ 売上KPI
B23: 保険料 | C23: =SUMIFS('freee実績'!$E:$E,'freee実績'!$B:$B,"2026-11",'freee実績'!$C:$C,"保険料") -> 0 | D23: 固定費 | G23: 指標 | H23: 数値 | J23: 算出方法 | L23: 人件費 総合計 | M23: =Q13+R13+M21 -> 0 | U23: ■ 営業利益
B24: 人件費（給与・社保） | C24: ='役員報酬・社保'!C17+'役員報酬・社保'!D17+'役員報酬・社保'!E17+'役員報酬・社保'!F71+86400 -> 297743.1 | D24: 変動費 | G24: 来客数（人） | H24: ='11月日次売上'!J34 -> 0 | U24: 項目 | V24: 計画 | W24: 実績 | X24: 差額 | Y24: 達成率
B25: 消耗品費 | C25: =SUMIFS('freee実績'!$E:$E,'freee実績'!$B:$B,"2026-11",'freee実績'!$C:$C,"消耗品費") -> 0 | D25: 変動費 | G25: 客単価 | H25: =IF(H24=0,0,H20/H24) -> 0 | J25: 売上÷来客数 | L25: ↑ この金額を左側「人件費（給与・社保）」に転記 | U25: 営業利益 | V25: ='売上計画'!J61 | W25: =I39 -> -312176.93 | X25: =W25-V25 -> -312176.93 | Y25: =IF(V25=0,0,W25/V25) -> 0
B26: 広告宣伝費 | C26: =SUMIFS('freee実績'!$E:$E,'freee実績'!$B:$B,"2026-11",'freee実績'!$C:$C,"広告宣伝費") -> 0 | D26: 変動費 | G26: 営業日数 | H26: 30 | U26: 営業利益率 | V26: ='売上計画'!J62 -> 768900 | W26: =IF(W8=0,0,W25/W8) -> 0 | X26: =W26-V26 -> -768900
B27: 修繕費 | C27: =SUMIFS('freee実績'!$E:$E,'freee実績'!$B:$B,"2026-11",'freee実績'!$C:$C,"修繕費") -> 0 | D27: 変動費 | G27: 日商（1日平均売上） | H27: =IF(H26=0,0,H20/H26) -> 0 | J27: 売上÷営業日数 | L27: ■ 人件費KPI
B28: その他経費 | C28: =SUMIFS('freee実績'!$E:$E,'freee実績'!$B:$B,"2026-11",'freee実績'!$C:$C,"雑費") -> 0 | D28: 変動費 | G28: 原価率 | H28: =IF(H20=0,0,C16/H20) -> 0 | J28: 原価÷売上 | L28: 指標 | M28: 数値 | R28: 算出方法
B29: 減価償却費 | C29: ='固定資産台帳'!S26 -> 14433.833 | D29: 帳簿上のみ | L29: 人件費率 | M29: =IF(H20=0,0,M23/H20) -> 0 | R29: 人件費÷売上
B30: 経費 合計 | C30: =SUM(C20:C29) -> 312176.93 | L30: 人時売上高 | M30: =IF((SUM(N5:N12)*SUM(O5:O12))=0,0,H20/(SUM(N5:N12)*SUM(O5:O12))) -> 0 | R30: 売上÷総労働時間
B32: ■ 一括経費（設備投資等） | G32: ■ 月次損益計算 | L32: ■ オーナー人件費 未払い管理
B33: 科目 | C33: 予算 | D33: 実績 | E33: 差額（残） | F33: メモ | H33: 項目 | I33: 金額 | L33: 帳簿上は計上、実際の支払いは利益が出てから
B34: 設備購入 | E34: =C34-D34 -> 0 | H34: 売上高 | I34: =H20 -> 0 | L34: 今月の人件費 支払い？ | M34: 未払い | N34: ← 「支払い」か「未払い」を入力
B35: 内装工事 | E35: =C35-D35 -> 0 | H35: 原価合計 | I35: =C16 -> 0 | L35: 人件費（帳簿計上額） | M35: =M23 -> 0 | N35: P/Lに反映
B36: その他一括経費 | E36: =C36-D36 -> 0 | H36: 粗利益 | I36: =I34-I35 -> 0 | L36: 実際の支払い額 | M36: =IF(M34="支払い",M35,0) -> 0 | N36: 口座から出るお金
E37: =C37-D37 -> 0 | H37: 粗利率 | I37: =IF(I34=0,0,I36/I34) -> 0 | L37: 今月の未払い額 | M37: =M35-M36 -> 0 | N37: 帳簿上は経費だが現金は出ない
E38: =C38-D38 -> 0 | H38: 経費合計 | I38: =C30 -> 312176.93 | L38: 前月までの未払い累計 | M38: ='10月'!M39 -> 0
E39: =C39-D39 -> 0 | H39: 営業利益 | I39: =I36-I38 -> -312176.93 | L39: 未払い累計（今月末時点） | M39: =M38+M37 -> 0 | N39: 将来支払う必要のある額
E40: =C40-D40 -> 0
E41: =C41-D41 -> 0 | L41: 過去の未払い分 今月支払額 | N41: 未払い累計から取り崩す場合に入力
...

Sheet 12月
B1: ☕ カフェ経営管理 ─ 12月 | U1: ■ 計画値（売上計画シートから自動取得）
B2: 月末口座（人件費なし） | C2: =I75 -> 835873.9 | E2: 今月出ていくお金 | F2: =C16+SUM(C20:C23)+SUM(C25:C28)+M36+D54+M41 -> 0 | H2: 今月の利益 | I2: =I39 -> -312176.93 | L2: 来月必要なお金 | M2: ='1月'!C20+'1月'!C21+'1月'!C22+'1月'!C23+'1月'!C25 -> 0 | U2: 実績の入力時に参考にしてください。差額・達成率も自動表示。
B3: ■ 資金（期首残高） | G3: ■ 売上（定期収入） | L3: ■ 人件費計算
B4: 科目 | C4: 金額 | D4: 詳細 | E4: メモ | G4: カテゴリ | H4: 金額 | I4: 詳細 | J4: メモ | L4: スタッフ名 | M4: 時給 | N4: 日数 | O4: 時間/日 | P4: 交通費/日 | Q4: 小計（給与） | R4: 小計（交通費） | U4: ■ 売上
B5: 前月繰越金 | C5: ='11月'!I75 -> 1133617 | G5: ドリンク（コーヒー） | H5: ='12月日次売上'!C35 -> 0 | Q5: =M5*N5*O5 -> 0 | R5: =P5*N5 -> 0 | U5: 項目 | V5: 計画 | W5: 実績 | X5: 差額 | Y5: 達成率
B6: 追加資金（借入等） | G6: ドリンク（紅茶・その他） | H6: ='12月日次売上'!D35 -> 0 | Q6: =M6*N6*O6 -> 0 | R6: =P6*N6 -> 0 | U6: 昼 来客数（季節調整後）/日 | V6: ='売上計画'!K38 -> 17 | W6: =IF(H26=0,"",H24/H26/2) -> 0 | X6: =IF(W6="",0,W6-V6) -> -17 | Y6: =IF(OR(W6="",V6=0),0,W6/V6) -> 0
B7: 期首資金 合計 | C7: =SUM(C5:C6) -> 1133617 | G7: フード（軽食） | H7: ='12月日次売上'!E35 -> 0 | Q7: =M7*N7*O7 -> 0 | R7: =P7*N7 -> 0 | U7: 夜 来客数（季節調整後）/日 | V7: ='売上計画'!K39 -> 23 | W7: =IF(H26=0,"",H24/H26/2) -> 0 | X7: =IF(W7="",0,W7-V7) -> -23 | Y7: =IF(OR(W7="",V7=0),0,W7/V7) -> 0
G8: フード（スイーツ） | H8: ='12月日次売上'!F35 -> 0 | Q8: =M8*N8*O8 -> 0 | R8: =P8*N8 -> 0 | U8: 売上合計（月間） | V8: ='売上計画'!K45 -> 1731350 | W8: =H20 -> 0 | X8: =W8-V8 -> -1731350 | Y8: =IF(V8=0,0,W8/V8) -> 0
B9: ■ 原価（売上原価） | G9: 物販（コーヒー豆・グッズ） | H9: ='12月日次売上'!G35 -> 0 | Q9: =M9*N9*O9 -> 0 | R9: =P9*N9 -> 0 | U9: 客単価 | V9: =IF((V6*'売上計画'!$C$7+V7*'売上計画'!$C$8)=0,0,V8/(V6*'売上計画'!$C$7+V7*'売上計画'!$C$8)) -> 1442.7917 | W9: =H25 -> 0 | X9: =W9-V9 -> -1442.7917 | Y9: =IF(V9=0,0,W9/V9) -> 0
B10: 科目 | C10: 金額 | D10: 詳細 | E10: メモ | G10: テイクアウト | H10: ='12月日次売上'!H35 -> 0 | Q10: =M10*N10*O10 -> 0 | R10: =P10*N10 -> 0
B11: コーヒー豆・茶葉 | C11: =SUMIFS('freee実績'!$E:$E,'freee実績'!$B:$B,"2026-12",'freee実績'!$C:$C,"仕入高",'freee実績'!$D:$D,"コーヒー豆・茶葉") -> 0 | G11: 売上 合計 | H11: =SUM(H5:H10) -> 0 | Q11: =M11*N11*O11 -> 0 | R11: =P11*N11 -> 0 | U11: ■ 原価・粗利
B12: 牛乳・シロップ等 | C12: =SUMIFS('freee実績'!$E:$E,'freee実績'!$B:$B,"2026-12",'freee実績'!$C:$C,"仕入高",'freee実績'!$D:$D,"牛乳・シロップ等") -> 0 | Q12: =M12*N12*O12 -> 0 | R12: =P12*N12 -> 0 | U12: 項目 | V12: 計画 | W12: 実績 | X12: 差額 | Y12: 原価率
B13: フード材料費 | C13: =SUMIFS('freee実績'!$E:$E,'freee実績'!$B:$B,"2026-12",'freee実績'!$C:$C,"仕入高",'freee実績'!$D:$D,"フード材料費") -> 0 | G13: ■ その他収入（不定期） | L13: アルバイト給与 合計 | Q13: =SUM(Q5:Q12) -> 0 | R13: =SUM(R5:R12) -> 0 | U13: 原価合計 | V13: ='売上計画'!K46 -> 519405 | W13: =C16 -> 0 | X13: =W13-V13 -> -519405 | Y13: =IF(W8=0,0,W13/W8) -> 0
B14: 包装資材・消耗品 | C14: =SUMIFS('freee実績'!$E:$E,'freee実績'!$B:$B,"2026-12",'freee実績'!$C:$C,"仕入高",'freee実績'!$D:$D,"包装資材・消耗品") -> 0 | G14: カテゴリ | H14: 金額 | I14: 詳細 | J14: メモ | U14: 粗利益 | V14: ='売上計画'!K47 -> 1211945 | W14: =H20-C16 -> 0 | X14: =W14-V14 -> -1211945 | Y14: =IF(W8=0,0,W14/W8) -> 0
B15: その他原価 | C15: =SUMIFS('freee実績'!$E:$E,'freee実績'!$B:$B,"2026-12",'freee実績'!$C:$C,"仕入高",'freee実績'!$D:$D,"その他原価") -> 0 | G15: イベント・貸切 | H15: ='12月日次売上'!I35 -> 0 | L15: ■ 固定人件費（役員報酬・社員給与等）
B16: 原価 合計 | C16: =SUM(C11:C15) -> 0 | G16: その他収入② | L16: 項目 | M16: 月額 | R16: 備考 | U16: ■ 経費
G17: その他収入 | L17: 役員報酬 | U17: 項目 | V17: 計画 | W17: 実績 | X17: 差額
B18: ■ 経費（販管費） | G18: その他収入 合計 | H18: =SUM(H15:H17) -> 0 | L18: 社員給与 | U18: 人件費（バイト+固定） | V18: ='売上計画'!K54 -> 46.5 | W18: =C24 -> 297743.1 | X18: =W18-V18 -> 297696.6
B19: 科目 | C19: 金額 | D19: 詳細 | E19: メモ | L19: 社会保険料（会社負担） | U19: 固定費（家賃+光熱+通信+保険） | V19: ='売上計画'!K57 -> 583.5 | W19: =C20+C21+C22+C23 -> 0 | X19: =W19-V19 -> -583.5
B20: 家賃 | C20: =SUMIFS('freee実績'!$E:$E,'freee実績'!$B:$B,"2026-12",'freee実績'!$C:$C,"地代家賃") -> 0 | D20: 固定費 | G20: 売上合計（定期＋不定期） | H20: =H11+H18 -> 0 | L20: その他人件費 | U20: 消耗品 | V20: ='売上計画'!K58 -> 0 | W20: =C25 -> 0 | X20: =W20-V20 -> 0
B21: 水道光熱費 | C21: =SUMIFS('freee実績'!$E:$E,'freee実績'!$B:$B,"2026-12",'freee実績'!$C:$C,"水道光熱費") -> 0 | D21: 固定費 | L21: 固定人件費 合計 | M21: =SUM(M17:M20) -> 0 | U21: 経費合計 | V21: ='売上計画'!K59 -> 0 | W21: =C30 -> 312176.93 | X21: =W21-V21 -> 312176.93
B22: 通信費 | C22: =SUMIFS('freee実績'!$E:$E,'freee実績'!$B:$B,"2026-12",'freee実績'!$C:$C,"通信費") -> 0 | D22: 固定費 | G22: ■ 売上KPI
B23: 保険料 | C23: =SUMIFS('freee実績'!$E:$E,'freee実績'!$B:$B,"2026-12",'freee実績'!$C:$C,"保険料") -> 0 | D23: 固定費 | G23: 指標 | H23: 数値 | J23: 算出方法 | L23: 人件費 総合計 | M23: =Q13+R13+M21 -> 0 | U23: ■ 営業利益
